Workbook
Name BaseVal: Assumptions!$P$9
Name beta: Assumptions!$D$22
Name Capacity: Assumptions!$D$36
Name CapDebt: Capitalization!$D$8
Name CapexIntensity: Assumptions!$D$38
Name cash: Assumptions!$D$24
Name CashYield: Assumptions!$D$35
Name ClassA: Assumptions!$D$13
Name ClassB: Assumptions!$D$14
Name DCFPrice: DCF!$E$37
Name Debt: Capitalization!$D$8
Name DepOpex: Assumptions!$D$34
Name DilutedShares: Assumptions!$D$17
Name DTA: Assumptions!$D$27
Name Enterprise: Tearsheet!$N$21
Name Exchange: Assumptions!$D$9
Name ExitMult: Assumptions!$D$41
Name ExitOverride: Assumptions!$D$40
Name FYE: Assumptions!$D$11
Name high: Assumptions!$D$19
Name HighVal: Assumptions!$P$10
Name Kd: Capitalization!$H$8
Name low: Assumptions!$D$20
Name LowVal: Assumptions!$P$11
Name marketcap: Assumptions!$D$18
Name MidYear: Assumptions!$D$43
Name mininterest: Assumptions!$D$28
Name Name: Assumptions!$D$7
Name NCIpct: Assumptions!$D$32
Name NetClaims: DCF!$E$40
Name prefstock: Assumptions!$D$29
Name rcash: Assumptions!$D$25
Name Recommendation: Assumptions!$D$4
Name RSUs: Assumptions!$D$15
Name Scenario: Assumptions!$C$45
Name shareprice: Assumptions!$D$12
Name shares: Assumptions!$D$16
Name TargetPrice: Assumptions!$L$13
Name TaxRate: Assumptions!$D$33
Name TerminalValue: DCF!$R$17
Name TGR: Assumptions!$D$39
Name Ticker: Assumptions!$D$8
Name TLAmort: Capitalization!$D$13
Name totaldebt: Assumptions!$D$23
Name TRA: Assumptions!$D$26
Name TV: DCF!$R$17
Name TVweight: Assumptions!$D$42
Name Util: Assumptions!$D$37
Name valdate: Assumptions!$D$10
Name WACC: WACC!$D$23
Name yield: Assumptions!$D$21

Sheet Tearsheet
C2: =Name&" ("&Exchange&": "&Ticker&")" -> Forgent Power Solutions, Inc. (NYSE: FPS) | H2: ="As of: "&TEXT(valdate,"mm/dd/yyyy") -> As of: 09/25/2026
C4: Tear Sheet | H4: Summary Statistics
C5: Business description: | H5: Stock rating | N5: =Recommendation -> Buy
C6: Forgent Power Solutions designs and manufactures electrical distribution equipment — switchgear, switchboards, dry-type and liquid-filled transformers, eHouses, PDUs and integrated power skids — for data center (59% of FY26 revenue), grid (21%), industrial (10%) and other customers, substantially all in North America. Formed through Neos Partners' 2023–24 roll-up of MGM Transformer, PwrQ, States Manufacturing and VanTran; IPO'd on the NYSE in February 2026 at $27.00. FY26 (June YE) revenue $1.42bn (+89%), adj. EBITDA $323m; backlog $3.0bn at 6/30/26. ~2.3m sq ft of leased plants in MN, TX, CA, MD and Mexico. [10-K FY26; Q4 FY26 release] | H6: Price target (base DCF) | N6: =TargetPrice -> 36.341509
H7: Valuation range (bear / bull, DCF + comps avg) | N7: =IF(OR(LowVal=0,HighVal=0),"run scenarios","$"&TEXT(LowVal,"0.00")&" – $"&TEXT(HighVal,"0.00")) -> $29.32 – $43.48
H8: Current price | N8: =shareprice -> 38.97
H9: Since-IPO low / high | N9: ="$"&TEXT(low,"0.00")&" / $"&TEXT(high,"0.00") -> $25.95 / $66.00
H10: % upside to target | N10: =N6/N8-1 -> -0.067449101
H12: Beta (relevered peer median) | N12: =beta -> 1.1673281
H13: Dividend yield | N13: =yield -> 0
H14: Diluted shares, fully exchanged (MM) | N14: =DilutedShares -> 305.12388
H16: Market capitalization ($MM) | N16: =marketcap -> 11863.594
C17: Investment thesis (analytical — analyst to confirm): | H17: + Debt ($MM) | N17: =totaldebt -> 598.5
C18: 1) Backlog-backed growth: $3.0bn backlog (~2.1x FY26 revenue) and a 3.3x Q4 book-to-bill underpin FY27 guidance of $2.4–2.6bn revenue (+76% at midpoint); FY26 beat the top of guidance after two raises. 2) Operating leverage on a largely built footprint: the 2025–26 capacity program is substantially complete (~$5bn revenue capacity, ~$5.8bn after the $35m PTS Tijuana expansion), so FY27 capex is guided to only ~$87m. 3) Margin ramp: adj. EBITDA margin rose from 20.4% (Q2) to 24.4% (Q4 FY26) as new plants reached rate; sponsor fees ended at IPO. 4) Technical overhang: shares fell from $55.86 (6/30) to $38.97 amid Neos secondary sales and the 8/4 lock-up expiry; Neos' stake is now 37.2% (Class B down from 90.2m to 29.9m units). The debate: the base-case DCF (below) vs. what the market already prices in on margin durability. | H18: + TRA, net of DTA & restricted cash ($MM) | N18: =TRA-DTA-rcash -> 33.718
H19: + Preferred & minority interest ($MM) | N19: =prefstock+mininterest -> 0
H20: − Cash & equivalents ($MM) | N20: =cash -> 97.477
H21: Enterprise value ($MM) | N21: =N16+N17+N18+N19-N20 -> 12398.335
H23: ="Financial projections — fiscal years ending "&TEXT(FYE,"mmmm d") -> Financial projections — fiscal years ending June 30
H24: All numbers in $MM except per-share data
I25: =Inc_Stmt!E5 -> FY26A | J25: =Inc_Stmt!F5 -> FY27E | K25: =Inc_Stmt!G5 -> FY28E | L25: =Inc_Stmt!H5 -> FY29E | M25: =Inc_Stmt!I5 -> FY30E | N25: =Inc_Stmt!J5 -> FY31E
H26: Revenue | I26: =Inc_Stmt!E12 -> 1420.059 | J26: =Inc_Stmt!F12 -> 2501.26 | K26: =Inc_Stmt!G12 -> 3266.9585 | L26: =Inc_Stmt!H12 -> 3909.8604 | M26: =Inc_Stmt!I12 -> 4448.1804 | N26: =Inc_Stmt!J12 -> 4886.6753
H27: YoY growth | I27: =Inc_Stmt!E67 -> 0.8853978 | J27: =Inc_Stmt!F67 -> 0.76137752 | K27: =Inc_Stmt!G67 -> 0.30612511 | L27: =Inc_Stmt!H67 -> 0.19678913 | M27: =Inc_Stmt!I67 -> 0.13768265 | N27: =Inc_Stmt!J67 -> 0.098578498
H28: Adj. EBITDA | I28: =Inc_Stmt!E43 -> 322.9 | J28: =Inc_Stmt!F43 -> 606.58909 | K28: =Inc_Stmt!G43 -> 843.80101 | L28: =Inc_Stmt!H43 -> 1031.2549 | M28: =Inc_Stmt!I43 -> 1170.4164 | N28: =Inc_Stmt!J43 -> 1275.3755
H29: YoY growth | I29: =Inc_Stmt!E69 -> 0.90839243 | J29: =Inc_Stmt!F69 -> 0.87856639 | K29: =Inc_Stmt!G69 -> 0.39105867 | L29: =Inc_Stmt!H69 -> 0.22215413 | M29: =Inc_Stmt!I69 -> 0.13494381 | N29: =Inc_Stmt!J69 -> 0.08967672
H30: EBITDA (GAAP) | I30: =Inc_Stmt!E40 -> 249.389 | J30: =Inc_Stmt!F40 -> 586.57901 | K30: =Inc_Stmt!G40 -> 817.66534 | L30: =Inc_Stmt!H40 -> 999.976 | M30: =Inc_Stmt!I40 -> 1134.8309 | N30: =Inc_Stmt!J40 -> 1236.2821
H31: Net income (incl. NCI) | I31: =Inc_Stmt!E30 -> 106.035 | J31: =Inc_Stmt!F30 -> 371.05367 | K31: =Inc_Stmt!G30 -> 542.58864 | L31: =Inc_Stmt!H30 -> 689.45005 | M31: =Inc_Stmt!I30 -> 802.78264 | N31: =Inc_Stmt!J30 -> 891.1284
H32: Diluted EPS (fully exchanged) | I32: =Inc_Stmt!E36 -> 0.34799803 | J32: =Inc_Stmt!F36 -> 1.2160755 | K32: =Inc_Stmt!G36 -> 1.7782569 | L32: =Inc_Stmt!H36 -> 2.2595742 | M32: =Inc_Stmt!I36 -> 2.6310056 | N32: =Inc_Stmt!J36 -> 2.9205462
H33: Unlevered FCF | I33: =Cash_Flow!E47 -> -10.40225 | J33: =Cash_Flow!F47 -> 230.76174 | K33: =Cash_Flow!G47 -> 495.51009 | L33: =Cash_Flow!H47 -> 635.749 | M33: =Cash_Flow!I47 -> 737.36404 | N33: =Cash_Flow!J47 -> 814.47244
C34: Catalysts: | H34: Capex | I34: =-Inc_Stmt!E44 -> 115.905 | J34: =-Inc_Stmt!F44 -> 87.0126 | K34: =-Inc_Stmt!G44 -> 39.203502 | L34: =-Inc_Stmt!H44 -> 50.828185 | M34: =-Inc_Stmt!I44 -> 62.274525 | N34: =-Inc_Stmt!J44 -> 73.30013
C35: • Q1 FY27 print (mgmt guides sequential revenue & EBITDA growth every quarter; Q1 burdened by hiring). • PTS Tijuana expansion online Q4 FY27 (+~$800m capacity). • Continued conversion of $3.0bn backlog; grid/utility share gains (utility sales ~$110m FY25 from <$50m). • Diminishing sponsor overhang as Neos sells down; sponsor consent rights lapse below 35%.
H36: EV / revenue | I36: =Enterprise/Inc_Stmt!E12 -> 8.7308589 | J36: =Enterprise/Inc_Stmt!F12 -> 4.9568357 | K36: =Enterprise/Inc_Stmt!G12 -> 3.7950696 | L36: =Enterprise/Inc_Stmt!H12 -> 3.1710428 | M36: =Enterprise/Inc_Stmt!I12 -> 2.7872824 | N36: =Enterprise/Inc_Stmt!J12 -> 2.5371718
H37: EV / adj. EBITDA | I37: =Enterprise/Inc_Stmt!E43 -> 38.396825 | J37: =Enterprise/Inc_Stmt!F43 -> 20.439429 | K37: =Enterprise/Inc_Stmt!G43 -> 14.693434 | L37: =Enterprise/Inc_Stmt!H43 -> 12.022571 | M37: =Enterprise/Inc_Stmt!I43 -> 10.593098 | N37: =Enterprise/Inc_Stmt!J43 -> 9.7213215
H38: P / E | I38: =shareprice/Inc_Stmt!E36 -> 111.98339 | J38: =shareprice/Inc_Stmt!F36 -> 32.045708 | K38: =shareprice/Inc_Stmt!G36 -> 21.914719 | L38: =shareprice/Inc_Stmt!H36 -> 17.246612 | M38: =shareprice/Inc_Stmt!I36 -> 14.811827 | N38: =shareprice/Inc_Stmt!J36 -> 13.343394
H39: Debt / adj. EBITDA | I39: =totaldebt/Inc_Stmt!E43 -> 1.853515 | J39: =totaldebt/Inc_Stmt!F43 -> 0.98666463 | K39: =totaldebt/Inc_Stmt!G43 -> 0.70929045 | L39: =totaldebt/Inc_Stmt!H43 -> 0.58036089 | M39: =totaldebt/Inc_Stmt!I43 -> 0.51135649 | N39: =totaldebt/Inc_Stmt!J43 -> 0.46927358
H40: Adj. EBITDA / interest | I40: =Inc_Stmt!E43/-Inc_Stmt!E22 -> 5.6523185 | J40: =Inc_Stmt!F43/-Inc_Stmt!F22 -> 15.860964 | K40: =Inc_Stmt!G43/-Inc_Stmt!G22 -> 22.28696 | L40: =Inc_Stmt!H43/-Inc_Stmt!H22 -> 27.51675 | M40: =Inc_Stmt!I43/-Inc_Stmt!I22 -> 31.552756 | N40: =Inc_Stmt!J43/-Inc_Stmt!J22 -> 34.741388
H42: Comparables analysis
I43: Mkt cap | J43: EV | K43: EV/LTM EBITDA | L43: LTM P/E | M43: NTM P/E
H44: =Ticker&" (at market)" -> FPS (at market) | I44: ='Comps Analysis'!E14 -> 11863.594 | J44: ='Comps Analysis'!G14 -> 12398.335 | K44: ='Comps Analysis'!D26 -> 38.396825 | L44: ='Comps Analysis'!E26 -> 111.98339 | M44: ='Comps Analysis'!F26 -> 29.08209
H45: Peer median | I45: =MEDIAN('Comps Analysis'!E7:E12) -> 62060.835 | J45: =MEDIAN('Comps Analysis'!G7:G12) -> 63781.101 | K45: ='Comps Analysis'!D30 -> 27.752828 | L45: ='Comps Analysis'!E30 -> 40.556455 | M45: ='Comps Analysis'!F30 -> 27.768465
C46: Risks: | H46: Peer max | I46: =MAX('Comps Analysis'!E7:E12) -> 255045.6 | J46: =MAX('Comps Analysis'!G7:G12) -> 247203.6 | K46: ='Comps Analysis'!D28 -> 62.901679 | L46: ='Comps Analysis'!E28 -> 57.303167 | M46: ='Comps Analysis'!F28 -> 43.146204
...

Sheet Assumptions
A1: ="Assumptions for "&Name -> Assumptions for Forgent Power Solutions, Inc.
A2: (Dollars in Millions unless stated)
B3: Valuation prepared by | D3: KJ | F3: HY Fund
B4: Recommendation | D4: Buy
B6: Company Information | D6: Input | F6: Name | J6: Share Price Outputs
B7: Company name | D7: Forgent Power Solutions, Inc. | F7: "Name" | H7: 10-K cover (FY26), filed 9/15/2026
B8: Ticker | D8: FPS | F8: "Ticker" | H8: 10-K cover | J8: Scenario | L8: DCF | N8: Comps | P8: Average
B9: Exchange | D9: NYSE | F9: "Exchange" | H9: 10-K cover | J9: =B46 -> Base | L9: 36.3415 | N9: ='Comps Analysis'!G43 -> 37.209743 | P9: =AVERAGE(L9,N9) -> 36.775621
B10: Valuation date | D10: 46290 | F10: "valdate" | H10: Last close used for price | J10: =B47 -> Bull | L10: 47.7447 | N10: ='Comps Analysis'!G42 -> 39.206242 | P10: =AVERAGE(L10,N10) -> 43.475471
B11: Last fiscal year end | D11: 46203 | F11: "FYE" | H11: 10-K: FY ends June 30 | J11: =B48 -> Bear | L11: 22.8707 | N11: ='Comps Analysis'!G44 -> 35.776725 | P11: =AVERAGE(L11,N11) -> 29.323712
B12: Last share price | D12: 38.97 | F12: "shareprice" | H12: Close 9/25/2026 — StockAnalysis / MarketBeat / MarketScreener | J12: Live DCF (current scenario) | L12: =DCF!E37 -> 36.341509
B13: Class A shares (MM) | D13: 274.52709 | F13: "ClassA" | H13: 10-K cover, as of 9/8/2026 | J13: Target Price (base DCF) | L13: =IF(Scenario=1,DCF!E37,L9) -> 36.341509
B14: Class B shares = exchangeable Opco units (MM) | D14: 29.901795 | F14: "ClassB" | H14: 10-K cover, as of 9/8/2026 (held by Neos vehicles) | J14: **DCF column L9:L11 is pasted from running each scenario (same convention as the Oracle model). Re-run Scenario 1/2/3 and re-paste if any driver changes.
B15: Unvested RSUs (MM) | D15: 0.694991 | F15: "RSUs" | H15: 10-K Note 20, 6/30/2026 (no options outstanding)
B16: Basic shares, fully exchanged (MM) | D16: =D13+D14 -> 304.42889 | F16: "shares" | H16: Up-C: Class B exchangeable 1:1 — value on fully-exchanged basis
B17: Diluted shares, fully exchanged (MM) | D17: =D16+D15 -> 305.12388 | F17: "DilutedShares" | H17: Basic + all RSUs (no strike -> no treasury method)
B18: Market cap ($MM) | D18: =shareprice*shares -> 11863.594 | F18: "marketcap"
B19: Since-IPO high | D19: 66 | F19: "high" | H19: StockAnalysis / MarketBeat (IPO 2/5/2026)
B20: Since-IPO low | D20: 25.95 | F20: "low" | H20: StockAnalysis / MarketBeat
B21: Dividend yield | D21: 0 | F21: "yield" | H21: 10-K Item 5: no dividend intended
B22: Beta (relevered peer median) | D22: =WACC!D36 -> 1.1673281 | F22: "beta" | H22: No usable FPS beta (<8 months trading) — see WACC tab
B23: Total debt ($MM, principal) | D23: =CapDebt -> 598.5 | F23: "totaldebt" | H23: Capitalization tab
B24: Cash & equivalents ($MM) | D24: 97.477 | F24: "cash" | H24: 10-K balance sheet 6/30/2026
B25: Restricted cash for TRA ($MM) | D25: 24.236 | F25: "rcash" | H25: 10-K: in prepaid & other current assets
B26: Tax receivable agreement liability ($MM) | D26: 338.925 | F26: "TRA" | H26: 10-K balance sheet 6/30/2026 (total liabilities less other lines)
B27: Deferred tax asset backing TRA ($MM) | D27: 280.971 | F27: "DTA" | H27: 10-K balance sheet 6/30/2026 (DTA, net)
B28: Minority interest subtracted in bridge ($MM) | D28: 0 | F28: "mininterest" | H28: Book NCI $107.1m NOT subtracted: Class B holders are already in the share count
B29: Preferred stock ($MM) | D29: 0 | F29: "prefstock" | H29: None outstanding
B31: Model Inputs
B32: NCI economic interest (Class B / fully exchanged) | D32: =ClassB/shares -> 0.098222593 | F32: "NCIpct" | H32: Used only to split GAAP net income
B33: Tax rate (normalized, fully exchanged) | D33: 0.25 | F33: "TaxRate" | H33: 21% federal + state; FY26 ETR 16.8% is depressed by untaxed NCI share
B34: Share of depreciation booked in opex | D34: 0.226 | F34: "DepOpex" | H34: 10-K Note 7: $4.3m of $19.0m FY26 depreciation in opex
B35: Interest yield on cash | D35: 0.025 | F35: "CashYield" | H35: FY26 interest income $2.8m on ~$104m avg cash = 2.7%
B36: Revenue capacity after FY27 expansion ($MM) | D36: 5800 | F36: "Capacity" | H36: Q4 FY26 release: ~$5bn today + ~$0.8bn PTS Tijuana expansion (online Q4 FY27)
B37: Max sustainable utilization | D37: 0.9 | F37: "Util" | H37: Analyst assumption — plants can't run at 100%
B38: Growth capex per $1 of new revenue capacity | D38: =35/800 -> 0.04375 | F38: "CapexIntensity" | H38: Q4 FY26 release: $35m PTS expansion adds ~$800m capacity
B39: Terminal growth rate (Gordon) | D39: 0.03 | F39: "TGR" | H39: <= long-run nominal GDP
B40: Exit EV/EBITDA override (blank = comps median) | D40: 14 | F40: "ExitOverride" | H40: 14.0x = mature-company exit for FY36 (growth ~3%): between precedent median (~12.6x) and 25th-pct peer EV / CY27E EBITDA (~15.5x) on 'Fwd Comps'. Blank reverts to peer EV/LTM median (27.8x), which implied ~7% perpetual growth (DCF!E47). At 14.0x DCF!E47 still shows ~4.7% (Gordon-consistent multiple ~10.3x), so 14.0x is not conservative.
B41: Exit EV/EBITDA multiple used | D41: =IF(ISNUMBER(ExitOverride),ExitOverride,'Comps Analysis'!D30) -> 14 | F41: "ExitMult"
B42: Weight on Gordon TV in blended TV | D42: 0.5 | F42: "TVweight" | H42: Oracle template averaged both methods; kept as an input
...

Sheet Inc_Stmt
A1: ="Income Statement for "&Name -> Income Statement for Forgent Power Solutions, Inc.
A2: (Dollars in Millions unless stated)
C4: ="Historical — fiscal years ending "&TEXT(FYE,"mmmm d") -> Historical — fiscal years ending June 30 | F4: ="Projected — fiscal years ending "&TEXT(FYE,"mmmm d") -> Projected — fiscal years ending June 30
C5: FY24PF | D5: FY25A | E5: FY26A | F5: FY27E | G5: FY28E | H5: FY29E | I5: FY30E | J5: FY31E | K5: FY32E | L5: FY33E | M5: FY34E | N5: FY35E | O5: FY36E
B7: Revenue
B8: Custom products | D8: 590.6 | E8: 990.5 | F8: =E8*(1+Assumptions!F55) -> 1525.37 | G8: =F8*(1+Assumptions!G55) -> 1906.7125 | H8: =G8*(1+Assumptions!H55) -> 2211.7865 | I8: =H8*(1+Assumptions!I55) -> 2455.083 | J8: =I8*(1+Assumptions!J55) -> 2651.4897 | K8: =J8*(1+Assumptions!K55) -> 2823.8365 | L8: =K8*(1+Assumptions!L55) -> 2979.1475 | M8: =L8*(1+Assumptions!M55) -> 3113.2091 | ... O8: =N8*(1+Assumptions!O55) -> 3318.8366 | Q8: 10-K Note 14 disaggregation ($0.1m rounding; PF FY24 by offering not disclosed)
B9: Powertrain solutions (PTS) | D9: 99.5 | E9: 357.4 | F9: =E9*(1+Assumptions!F60) -> 893.5 | G9: =F9*(1+Assumptions!G60) -> 1268.77 | H9: =G9*(1+Assumptions!H60) -> 1598.6502 | I9: =H9*(1+Assumptions!I60) -> 1886.4072 | J9: =I9*(1+Assumptions!J60) -> 2122.2081 | K9: =J9*(1+Assumptions!K60) -> 2334.429 | L9: =K9*(1+Assumptions!L60) -> 2509.5111 | M9: =L9*(1+Assumptions!M60) -> 2647.5342 | ... O9: =N9*(1+Assumptions!O60) -> 2849.6735
B10: Standard products | D10: 34.6 | E10: 42.5 | F10: =E10*(1+Assumptions!F65) -> 46.75 | G10: =F10*(1+Assumptions!G65) -> 50.49 | H10: =G10*(1+Assumptions!H65) -> 53.5194 | I10: =H10*(1+Assumptions!I65) -> 56.19537 | J10: =I10*(1+Assumptions!J65) -> 58.443185 | K10: =J10*(1+Assumptions!K65) -> 60.780912 | L10: =K10*(1+Assumptions!L65) -> 62.908244 | M10: =L10*(1+Assumptions!M65) -> 64.795491 | ... O10: =N10*(1+Assumptions!O65) -> 68.741537
B11: Services | D11: 28.4 | E11: 29.7 | F11: =E11*(1+Assumptions!F70) -> 35.64 | G11: =F11*(1+Assumptions!G70) -> 40.986 | H11: =G11*(1+Assumptions!H70) -> 45.90432 | I11: =H11*(1+Assumptions!I70) -> 50.494752 | J11: =I11*(1+Assumptions!J70) -> 54.534332 | K11: =J11*(1+Assumptions!K70) -> 58.351735 | L11: =K11*(1+Assumptions!L70) -> 61.85284 | M11: =L11*(1+Assumptions!M70) -> 64.945482 | ... O11: =N11*(1+Assumptions!O70) -> 69.904069
B12: Total revenue | C12: 482.7 | D12: 753.188 | E12: 1420.059 | F12: =SUM(F8:F11) -> 2501.26 | G12: =SUM(G8:G11) -> 3266.9585 | H12: =SUM(H8:H11) -> 3909.8604 | I12: =SUM(I8:I11) -> 4448.1804 | J12: =SUM(J8:J11) -> 4886.6753 | K12: =SUM(K8:K11) -> 5277.3981 | L12: =SUM(L8:L11) -> 5613.4197 | M12: =SUM(M8:M11) -> 5890.4843 | ... O12: =SUM(O8:O11) -> 6307.1557 | Q12: PF FY24: IPO 424B4 pro forma (all acquisitions from 7/1/23); FY25–26: 10-K
B14: Cost of revenues (incl. depreciation) | C14: -292.3 | D14: -475.122 | E14: -922.459 | F14: =-F12*(1-Assumptions!F75) -> -1600.8064 | G14: =-G12*(1-Assumptions!G75) -> -2074.5186 | H14: =-H12*(1-Assumptions!H75) -> -2471.0318 | I14: =-I12*(1-Assumptions!I75) -> -2811.25 | J14: =-J12*(1-Assumptions!J75) -> -3098.1521 | K14: =-K12*(1-Assumptions!K75) -> -3366.98 | L14: =-L12*(1-Assumptions!L75) -> -3603.8154 | M14: =-M12*(1-Assumptions!M75) -> -3805.2529 | ... O14: =-O12*(1-Assumptions!O75) -> -4112.2655 | Q14: FY26 COGS includes $14.7m depreciation (10-K Note 7)
B15: Gross profit | C15: =C12+C14 -> 190.4 | D15: =D12+D14 -> 278.066 | E15: =E12+E14 -> 497.6 | F15: =F12+F14 -> 900.4536 | G15: =G12+G14 -> 1192.4399 | H15: =H12+H14 -> 1438.8286 | I15: =I12+I14 -> 1636.9304 | J15: =J12+J14 -> 1788.5232 | ... O15: =O12+O14 -> 2194.8902
B17: Selling, general & administrative | C17: -100.7 | D17: -146.27 | E17: -262.886 | F17: =-F12*Assumptions!F80 -> -337.6701 | G17: =-G12*Assumptions!G80 -> -405.10285 | H17: =-H12*Assumptions!H80 -> -469.18325 | I17: =-I12*Assumptions!I80 -> -533.78164 | J17: =-J12*Assumptions!J80 -> -586.40104 | K17: =-K12*Assumptions!K80 -> -643.84257 | L17: =-L12*Assumptions!L80 -> -696.06404 | M17: =-M12*Assumptions!M80 -> -742.20103 | ... O17: =-O12*Assumptions!O80 -> -819.93024
B18: Depreciation & amortization (opex line) | C18: -71.3 | D18: -59.559 | E18: -52.225 | F18: =-(F38+F37*DepOpex) -> -32.238042 | G18: =-(G38+G37*DepOpex) -> -33.909563 | H18: =-(H38+H37*DepOpex) -> -33.115227 | I18: =-(I38+I37*DepOpex) -> -32.093869 | J18: =-(J38+J37*DepOpex) -> -32.817345 | K18: =-(K38+K37*DepOpex) -> -33.806068 | L18: =-(L38+L37*DepOpex) -> -34.939752 | M18: =-(M38+M37*DepOpex) -> -36.533398 | ... O18: =-(O38+O37*DepOpex) -> -39.166107 | Q18: Projected = intangible amortization + opex share of depreciation
B20: Operating income (EBIT) | C20: =C15+C17+C18 -> 18.4 | D20: =D15+D17+D18 -> 72.237 | E20: =E15+E17+E18 -> 182.489 | F20: =F15+F17+F18 -> 530.54546 | G20: =G15+G17+G18 -> 753.42744 | H20: =H15+H17+H18 -> 936.53016 | I20: =I15+I17+I18 -> 1071.0549 | J20: =J15+J17+J18 -> 1169.3048 | ... O20: =O15+O17+O18 -> 1335.7938
B22: Interest expense | C22: -58.7 | D22: -54.778 | E22: -57.127 | F22: =-Capitalization!F22 -> -38.24415 | G22: =-Capitalization!G22 -> -37.86075 | H22: =-Capitalization!H22 -> -37.47735 | I22: =-Capitalization!I22 -> -37.09395 | J22: =-Capitalization!J22 -> -36.71055 | K22: =-Capitalization!K22 -> -36.32715 | L22: =-Capitalization!L22 -> -35.94375 | M22: =-Capitalization!M22 -> -35.56035 | ... O22: =-Capitalization!O22 -> -34.79355 | Q22: Capitalization tab: beginning term-loan balance x 6.39%
B23: Interest income | C23: 4.4 | D23: 5.558 | E23: 2.787 | F23: =Bal_Sht!E7*CashYield -> 2.436925 | G23: =Bal_Sht!F7*CashYield -> 7.8848351 | H23: =Bal_Sht!G7*CashYield -> 20.213931 | I23: =Bal_Sht!H7*CashYield -> 36.415939 | J23: =Bal_Sht!I7*CashYield -> 55.576963 | K23: =Bal_Sht!J7*CashYield -> 77.119854 | L23: =Bal_Sht!K7*CashYield -> 100.34565 | M23: =Bal_Sht!L7*CashYield -> 124.76445 | ... O23: =Bal_Sht!N7*CashYield -> 177.40689 | Q23: Beginning cash x CashYield (no circularity)
B24: Other non-operating income / (expense) | C24: -0.6 | D24: -0.231 | E24: -0.749 | F24: 0 | G24: 0 | H24: 0 | I24: 0 | J24: 0 | K24: 0 | L24: 0 | M24: 0 | N24: 0 | O24: 0
B26: Earnings before income taxes | C26: =SUM(C20:C24) -> -36.5 | D26: =SUM(D20:D24) -> 22.786 | E26: =SUM(E20:E24) -> 127.4 | F26: =SUM(F20:F24) -> 494.73823 | G26: =SUM(G20:G24) -> 723.45152 | H26: =SUM(H20:H24) -> 919.26674 | I26: =SUM(I20:I24) -> 1070.3769 | J26: =SUM(J20:J24) -> 1188.1712 | ... O26: =SUM(O20:O24) -> 1478.4072
B28: Income tax (expense) / benefit | C28: 8.4 | D28: -5.34 | E28: -21.365 | F28: =-F26*TaxRate -> -123.68456 | G28: =-G26*TaxRate -> -180.86288 | H28: =-H26*TaxRate -> -229.81668 | I28: =-I26*TaxRate -> -267.59421 | J28: =-J26*TaxRate -> -297.0428 | K28: =-K26*TaxRate -> -318.39054 | L28: =-L26*TaxRate -> -335.75059 | M28: =-M26*TaxRate -> -348.92528 | ... O28: =-O26*TaxRate -> -369.60179 | Q28: Normalized 25% (fully exchanged); history as reported
B30: Net income (incl. NCI) | C30: =C26+C28 -> -28.1 | D30: =D26+D28 -> 17.446 | E30: =E26+E28 -> 106.035 | F30: =F26+F28 -> 371.05367 | G30: =G26+G28 -> 542.58864 | H30: =H26+H28 -> 689.45005 | I30: =I26+I28 -> 802.78264 | J30: =J26+J28 -> 891.1284 | ... O30: =O26+O28 -> 1108.8054
B31: Less: net income attributable to NCI | C31: 8.7 | D31: -2.25 | E31: -24.19 | F31: =-F30*NCIpct -> -36.445854 | G31: =-G30*NCIpct -> -53.294463 | H31: =-H30*NCIpct -> -67.719572 | I31: =-I30*NCIpct -> -78.851393 | J31: =-J30*NCIpct -> -87.528942 | K31: =-K30*NCIpct -> -93.819435 | L31: =-L30*NCIpct -> -98.934881 | M31: =-M30*NCIpct -> -102.81704 | ... O31: =-O30*NCIpct -> -108.90974 | Q31: Projected at Class B share of Opco (9.82% post-July 2026 follow-on)
B32: Net income attributable to FPS | C32: =C30+C31 -> -19.4 | D32: =D30+D31 -> 15.196 | E32: =E30+E31 -> 81.845 | F32: =F30+F31 -> 334.60782 | G32: =G30+G31 -> 489.29418 | H32: =H30+H31 -> 621.73048 | I32: =I30+I31 -> 723.93125 | J32: =J30+J31 -> 803.59945 | ... O32: =O30+O31 -> 999.89563
B34: Supplemental information
B35: Diluted shares, fully exchanged (MM) | E35: 304.7 | F35: =DilutedShares -> 305.12388 | G35: =DilutedShares -> 305.12388 | H35: =DilutedShares -> 305.12388 | I35: =DilutedShares -> 305.12388 | J35: =DilutedShares -> 305.12388 | K35: =DilutedShares -> 305.12388 | L35: =DilutedShares -> 305.12388 | M35: =DilutedShares -> 305.12388 | ... O35: =DilutedShares -> 305.12388 | Q35: FY26: company adj. diluted weighted shares (10-K MD&A); FY24–25 pre-IPO n/a
B36: Diluted EPS, fully exchanged (GAAP NI incl. NCI / shares) | E36: =E30/E35 -> 0.34799803 | F36: =F30/F35 -> 1.2160755 | G36: =G30/G35 -> 1.7782569 | H36: =H30/H35 -> 2.2595742 | I36: =I30/I35 -> 2.6310056 | J36: =J30/J35 -> 2.9205462 | K36: =K30/K35 -> 3.1304388 | L36: =L30/L35 -> 3.301124 | ... O36: =O30/O35 -> 3.6339515 | Q36: Reported GAAP Class A EPS $0.30 covers 2/6–6/30/26 only; this is the full-year economic EPS
B37: Depreciation (total) | C37: 3.4 | D37: 6.2 | E37: 19 | F37: =Assumptions!F90*Bal_Sht!E16 -> 30.74355 | G37: =Assumptions!G90*Bal_Sht!F16 -> 39.183907 | H37: =Assumptions!H90*Bal_Sht!G16 -> 39.186847 | I37: =Assumptions!I90*Bal_Sht!H16 -> 40.933047 | J37: =Assumptions!J90*Bal_Sht!I16 -> 44.134269 | K37: =Assumptions!K90*Bal_Sht!J16 -> 48.509148 | L37: =Assumptions!L90*Bal_Sht!K16 -> 53.525449 | M37: =Assumptions!M90*Bal_Sht!L16 -> 60.576984 | ... O37: =Assumptions!O90*Bal_Sht!N16 -> 72.226136
B38: Amortization of intangibles | C38: 70.1 | D38: 58.7 | E38: 47.9 | F38: =MIN(Assumptions!F135,Bal_Sht!E19) -> 25.29 | G38: =MIN(Assumptions!G135,Bal_Sht!F19) -> 25.054 | H38: =MIN(Assumptions!H135,Bal_Sht!G19) -> 24.259 | I38: =MIN(Assumptions!I135,Bal_Sht!H19) -> 22.843 | J38: =MIN(Assumptions!J135,Bal_Sht!I19) -> 22.843 | K38: =MIN(Assumptions!K135,Bal_Sht!J19) -> 22.843 | L38: =MIN(Assumptions!L135,Bal_Sht!K19) -> 22.843 | M38: =MIN(Assumptions!M135,Bal_Sht!L19) -> 22.843 | ... O38: =MIN(Assumptions!O135,Bal_Sht!N19) -> 22.843
B39: Total D&A | C39: =C37+C38 -> 73.5 | D39: =D37+D38 -> 64.9 | E39: =E37+E38 -> 66.9 | F39: =F37+F38 -> 56.03355 | G39: =G37+G38 -> 64.237907 | H39: =H37+H38 -> 63.445847 | I39: =I37+I38 -> 63.776047 | J39: =J37+J38 -> 66.977269 | ... O39: =O37+O38 -> 95.069136
B40: EBITDA (GAAP: EBIT + D&A) | C40: =C20+C39 -> 91.9 | D40: =D20+D39 -> 137.137 | E40: =E20+E39 -> 249.389 | F40: =F20+F39 -> 586.57901 | G40: =G20+G39 -> 817.66534 | H40: =H20+H39 -> 999.976 | I40: =I20+I39 -> 1134.8309 | J40: =J20+J39 -> 1236.2821 | ... O40: =O20+O39 -> 1430.863
B41: Stock-based compensation | C41: 1.5 | D41: 1.784 | E41: 10.036 | F41: =F12*Assumptions!F85 -> 20.01008 | G41: =G12*Assumptions!G85 -> 26.135668 | H41: =H12*Assumptions!H85 -> 31.278883 | I41: =I12*Assumptions!I85 -> 35.585443 | J41: =J12*Assumptions!J85 -> 39.093403 | K41: =K12*Assumptions!K85 -> 42.219185 | L41: =L12*Assumptions!L85 -> 44.907358 | M41: =M12*Assumptions!M85 -> 47.123875 | ... O41: =O12*Assumptions!O85 -> 50.457245
B42: IPO / sponsor / integration one-offs | C42: 6.4 | D42: 30.6 | E42: 64.2 | F42: 0 | G42: 0 | H42: 0 | I42: 0 | J42: 0 | K42: 0 | L42: 0 | M42: 0 | N42: 0 | O42: 0 | Q42: FY26: sponsor fees 18.8 + public-co readiness 21.2 + earnout 5.4 + integration 18.8 (Q4 FY26 release recon)
B43: Adj. EBITDA (company definition) | C43: 99.2 | D43: 169.2 | E43: 322.9 | F43: =F40+F41+F42 -> 606.58909 | G43: =G40+G41+G42 -> 843.80101 | H43: =H40+H41+H42 -> 1031.2549 | I43: =I40+I41+I42 -> 1170.4164 | J43: =J40+J41+J42 -> 1275.3755 | K43: =K40+K41+K42 -> 1346.3408 | L43: =L40+L41+L42 -> 1399.8763 | M43: =M40+M41+M42 -> 1437.0409 | ... O43: =O40+O41+O42 -> 1481.3202 | Q43: History as reported; FY27 guidance $575–625m
B44: Capital expenditures | D44: -84.115 | E44: -115.905 | F44: =-SUM(F45:F47) -> -87.0126 | G44: =-SUM(G45:G47) -> -39.203502 | H44: =-SUM(H45:H47) -> -50.828185 | I44: =-SUM(I45:I47) -> -62.274525 | J44: =-SUM(J45:J47) -> -73.30013 | K44: =-SUM(K45:K47) -> -81.951156 | L44: =-SUM(L45:L47) -> -100.53568 | M44: =-SUM(M45:M47) -> -101.82568 | ... O44: =-SUM(O45:O47) -> -103.53737
B45: Maintenance | F45: =F12*Assumptions!F95 -> 25.0126 | G45: =G12*Assumptions!G95 -> 39.203502 | H45: =H12*Assumptions!H95 -> 50.828185 | I45: =I12*Assumptions!I95 -> 62.274525 | J45: =J12*Assumptions!J95 -> 73.30013 | K45: =K12*Assumptions!K95 -> 79.160971 | L45: =L12*Assumptions!L95 -> 84.201296 | M45: =M12*Assumptions!M95 -> 88.357265 | ... O45: =O12*Assumptions!O95 -> 94.607335
B46: Committed expansion | F46: =Assumptions!F100 -> 62 | G46: =Assumptions!G100 -> 0 | H46: =Assumptions!H100 -> 0 | I46: =Assumptions!I100 -> 0 | J46: =Assumptions!J100 -> 0 | K46: =Assumptions!K100 -> 0 | L46: =Assumptions!L100 -> 0 | M46: =Assumptions!M100 -> 0 | ... O46: =Assumptions!O100 -> 0
B47: Capacity-driven growth capex | F47: =(F49-Capacity)*CapexIntensity -> 0 | G47: =(G49-F49)*CapexIntensity -> 0 | H47: =(H49-G49)*CapexIntensity -> 0 | I47: =(I49-H49)*CapexIntensity -> 0 | J47: =(J49-I49)*CapexIntensity -> 0 | K47: =(K49-J49)*CapexIntensity -> 2.7901847 | L47: =(L49-K49)*CapexIntensity -> 16.334384 | M47: =(M49-L49)*CapexIntensity -> 13.46842 | N47: =(N49-M49)*CapexIntensity -> 11.324822 | O47: =(O49-N49)*CapexIntensity -> 8.9300343
B49: Revenue capacity, end of year | F49: =MAX(Capacity,F12/Util) -> 5800 | G49: =MAX(F49,G12/Util) -> 5800 | H49: =MAX(G49,H12/Util) -> 5800 | I49: =MAX(H49,I12/Util) -> 5800 | J49: =MAX(I49,J12/Util) -> 5800 | K49: =MAX(J49,K12/Util) -> 5863.7757 | L49: =MAX(K49,L12/Util) -> 6237.133 | M49: =MAX(L49,M12/Util) -> 6544.9826 | N49: =MAX(M49,N12/Util) -> 6803.8357 | O49: =MAX(N49,O12/Util) -> 7007.9507 | Q49: Capacity only expands once revenue / Util exceeds it; growth capex = new capacity x intensity
B50: Utilization (revenue / capacity) | F50: =F12/F49 -> 0.43125172 | G50: =G12/G49 -> 0.56326871 | H50: =H12/H49 -> 0.67411387 | I50: =I12/I49 -> 0.76692765 | J50: =J12/J49 -> 0.84253023 | K50: =K12/K49 -> 0.9 | L50: =L12/L49 -> 0.9 | M50: =M12/M49 -> 0.9 | ... O50: =O12/O49 -> 0.9
B52: Net working capital (AR + inv + prepaid − AP − accrued − deposits) | D52: =Bal_Sht!D8+Bal_Sht!D9+Bal_Sht!D10-Bal_Sht!D25-Bal_Sht!D26-Bal_Sht!D28 -> 81.446 | E52: =Bal_Sht!E8+Bal_Sht!E9+Bal_Sht!E10-Bal_Sht!E25-Bal_Sht!E26-Bal_Sht!E28 -> 179.71 | F52: =Bal_Sht!F8+Bal_Sht!F9+Bal_Sht!F10-Bal_Sht!F25-Bal_Sht!F26-Bal_Sht!F28 -> 315.8783 | G52: =Bal_Sht!G8+Bal_Sht!G9+Bal_Sht!G10-Bal_Sht!G25-Bal_Sht!G26-Bal_Sht!G28 -> 410.4732 | H52: =Bal_Sht!H8+Bal_Sht!H9+Bal_Sht!H10-Bal_Sht!H25-Bal_Sht!H26-Bal_Sht!H28 -> 489.73948 | I52: =Bal_Sht!I8+Bal_Sht!I9+Bal_Sht!I10-Bal_Sht!I25-Bal_Sht!I26-Bal_Sht!I28 -> 557.16811 | J52: =Bal_Sht!J8+Bal_Sht!J9+Bal_Sht!J10-Bal_Sht!J25-Bal_Sht!J26-Bal_Sht!J28 -> 613.35139 | K52: =Bal_Sht!K8+Bal_Sht!K9+Bal_Sht!K10-Bal_Sht!K25-Bal_Sht!K26-Bal_Sht!K28 -> 665.1112 | ... O52: =Bal_Sht!O8+Bal_Sht!O9+Bal_Sht!O10-Bal_Sht!O25-Bal_Sht!O26-Bal_Sht!O28 -> 806.26185
...

Sheet Bal_Sht
A1: ="Balance Sheet for "&Name -> Balance Sheet for Forgent Power Solutions, Inc.
A2: (Dollars in Millions unless stated)
C4: ="Historical — fiscal years ending "&TEXT(FYE,"mmmm d") -> Historical — fiscal years ending June 30 | F4: ="Projected — fiscal years ending "&TEXT(FYE,"mmmm d") -> Projected — fiscal years ending June 30
C5: n/a | D5: FY25A | E5: FY26A | F5: FY27E | G5: FY28E | H5: FY29E | I5: FY30E | J5: FY31E | K5: FY32E | L5: FY33E | M5: FY34E | N5: FY35E | O5: FY36E
B6: Assets
B7: Cash & equivalents | D7: 111.322 | E7: 97.477 | F7: =Cash_Flow!F41 -> 315.3934 | G7: =Cash_Flow!G41 -> 808.55722 | H7: =Cash_Flow!H41 -> 1456.6375 | I7: =Cash_Flow!I41 -> 2223.0785 | J7: =Cash_Flow!J41 -> 3084.7942 | K7: =Cash_Flow!K41 -> 4013.8262 | L7: =Cash_Flow!L41 -> 4990.5779 | M7: =Cash_Flow!M41 -> 6021.9767 | ... O7: =Cash_Flow!O41 -> 8216.0095 | Q7: 10-K balance sheets (XBRL, $000s / 1,000)
B8: Accounts receivable, net | D8: 159.97 | E8: 329.628 | F8: =Assumptions!F105/365*Inc_Stmt!F12 -> 582.48521 | G8: =Assumptions!G105/365*Inc_Stmt!G12 -> 760.79855 | H8: =Assumptions!H105/365*Inc_Stmt!H12 -> 910.51544 | I8: =Assumptions!I105/365*Inc_Stmt!I12 -> 1035.8776 | J8: =Assumptions!J105/365*Inc_Stmt!J12 -> 1137.9929 | K8: =Assumptions!K105/365*Inc_Stmt!K12 -> 1228.9831 | L8: =Assumptions!L105/365*Inc_Stmt!L12 -> 1307.2347 | M8: =Assumptions!M105/365*Inc_Stmt!M12 -> 1371.7566 | ... O8: =Assumptions!O105/365*Inc_Stmt!O12 -> 1468.7897
B9: Inventory, net | D9: 117.577 | E9: 249.817 | F9: =Assumptions!F110/365*-Inc_Stmt!F14 -> 434.19132 | G9: =Assumptions!G110/365*-Inc_Stmt!G14 -> 562.67766 | H9: =Assumptions!H110/365*-Inc_Stmt!H14 -> 670.22506 | I9: =Assumptions!I110/365*-Inc_Stmt!I14 -> 762.50342 | J9: =Assumptions!J110/365*-Inc_Stmt!J14 -> 840.32072 | K9: =Assumptions!K110/365*-Inc_Stmt!K14 -> 913.23567 | L9: =Assumptions!L110/365*-Inc_Stmt!L14 -> 977.47323 | M9: =Assumptions!M110/365*-Inc_Stmt!M14 -> 1032.1097 | ... O9: =Assumptions!O110/365*-Inc_Stmt!O14 -> 1115.3816
B10: Prepaid & other current (ex restricted cash) | D10: 56.278 | E10: 116.933 | F10: =Assumptions!F120*Inc_Stmt!F12 -> 205.10332 | G10: =Assumptions!G120*Inc_Stmt!G12 -> 267.8906 | H10: =Assumptions!H120*Inc_Stmt!H12 -> 320.60855 | I10: =Assumptions!I120*Inc_Stmt!I12 -> 364.75079 | J10: =Assumptions!J120*Inc_Stmt!J12 -> 400.70738 | K10: =Assumptions!K120*Inc_Stmt!K12 -> 432.74664 | L10: =Assumptions!L120*Inc_Stmt!L12 -> 460.30042 | M10: =Assumptions!M120*Inc_Stmt!M12 -> 483.01972 | ... O10: =Assumptions!O120*Inc_Stmt!O12 -> 517.18677 | Q10: Reported $141.2m less $24.2m TRA-restricted cash
B11: Restricted cash (TRA) | D11: 0 | E11: 24.236 | F11: =E11 -> 24.236 | G11: =F11 -> 24.236 | H11: =G11 -> 24.236 | I11: =H11 -> 24.236 | J11: =I11 -> 24.236 | K11: =J11 -> 24.236 | L11: =K11 -> 24.236 | M11: =L11 -> 24.236 | ... O11: =N11 -> 24.236
B12: Total current assets | D12: =SUM(D7:D11) -> 445.147 | E12: =SUM(E7:E11) -> 818.091 | F12: =SUM(F7:F11) -> 1561.4093 | G12: =SUM(G7:G11) -> 2424.16 | H12: =SUM(H7:H11) -> 3382.2226 | I12: =SUM(I7:I11) -> 4410.4464 | J12: =SUM(J7:J11) -> 5488.0511 | K12: =SUM(K7:K11) -> 6613.0276 | ... O12: =SUM(O7:O11) -> 11341.603
B14: Gross PP&E | D14: 115.52 | E14: 229.331 | F14: =E14-Inc_Stmt!F44 -> 316.3436 | G14: =F14-Inc_Stmt!G44 -> 355.5471 | H14: =G14-Inc_Stmt!H44 -> 406.37529 | I14: =H14-Inc_Stmt!I44 -> 468.64981 | J14: =I14-Inc_Stmt!J44 -> 541.94994 | K14: =J14-Inc_Stmt!K44 -> 623.9011 | L14: =K14-Inc_Stmt!L44 -> 724.43678 | M14: =L14-Inc_Stmt!M44 -> 826.26246 | ... O14: =N14-Inc_Stmt!O44 -> 1032.9764
B15: Accumulated depreciation | D15: -7.35 | E15: -24.374 | F15: =E15-Inc_Stmt!F37 -> -55.11755 | G15: =F15-Inc_Stmt!G37 -> -94.301457 | H15: =G15-Inc_Stmt!H37 -> -133.4883 | I15: =H15-Inc_Stmt!I37 -> -174.42135 | J15: =I15-Inc_Stmt!J37 -> -218.55562 | K15: =J15-Inc_Stmt!K37 -> -267.06477 | L15: =K15-Inc_Stmt!L37 -> -320.59022 | M15: =L15-Inc_Stmt!M37 -> -381.1672 | ... O15: =N15-Inc_Stmt!O37 -> -520.15763
B16: Net PP&E | D16: =D14+D15 -> 108.17 | E16: =E14+E15 -> 204.957 | F16: =F14+F15 -> 261.22605 | G16: =G14+G15 -> 261.24564 | H16: =H14+H15 -> 272.88698 | I16: =I14+I15 -> 294.22846 | J16: =J14+J15 -> 323.39432 | K16: =K14+K15 -> 356.83633 | ... O16: =O14+O15 -> 512.81881
B17: Operating lease ROU assets | D17: 117.769 | E17: 108.432 | F17: =E17 -> 108.432 | G17: =F17 -> 108.432 | H17: =G17 -> 108.432 | I17: =H17 -> 108.432 | J17: =I17 -> 108.432 | K17: =J17 -> 108.432 | L17: =K17 -> 108.432 | M17: =L17 -> 108.432 | ... O17: =N17 -> 108.432
B18: Goodwill | D18: 516.629 | E18: 516.629 | F18: =E18 -> 516.629 | G18: =F18 -> 516.629 | H18: =G18 -> 516.629 | I18: =H18 -> 516.629 | J18: =I18 -> 516.629 | K18: =J18 -> 516.629 | L18: =K18 -> 516.629 | M18: =L18 -> 516.629 | ... O18: =N18 -> 516.629
B19: Intangible assets, net | D19: 337.271 | E19: 289.49 | F19: =E19-Inc_Stmt!F38 -> 264.2 | G19: =F19-Inc_Stmt!G38 -> 239.146 | H19: =G19-Inc_Stmt!H38 -> 214.887 | I19: =H19-Inc_Stmt!I38 -> 192.044 | J19: =I19-Inc_Stmt!J38 -> 169.201 | K19: =J19-Inc_Stmt!K38 -> 146.358 | L19: =K19-Inc_Stmt!L38 -> 123.515 | M19: =L19-Inc_Stmt!M38 -> 100.672 | ... O19: =N19-Inc_Stmt!O38 -> 54.986
B20: Deferred tax assets, net | D20: 0 | E20: 280.971 | F20: =E20 -> 280.971 | G20: =F20 -> 280.971 | H20: =G20 -> 280.971 | I20: =H20 -> 280.971 | J20: =I20 -> 280.971 | K20: =J20 -> 280.971 | L20: =K20 -> 280.971 | M20: =L20 -> 280.971 | ... O20: =N20 -> 280.971
B21: Other long-term assets | D21: 11.7 | E21: 12.195 | F21: =E21 -> 12.195 | G21: =F21 -> 12.195 | H21: =G21 -> 12.195 | I21: =H21 -> 12.195 | J21: =I21 -> 12.195 | K21: =J21 -> 12.195 | L21: =K21 -> 12.195 | M21: =L21 -> 12.195 | ... O21: =N21 -> 12.195
B22: Total assets | D22: =D12+D16+SUM(D17:D21) -> 1536.686 | E22: =E12+E16+SUM(E17:E21) -> 2230.765 | F22: =F12+F16+SUM(F17:F21) -> 3005.0623 | G22: =G12+G16+SUM(G17:G21) -> 3842.7787 | H22: =H12+H16+SUM(H17:H21) -> 4788.2236 | I22: =I12+I16+SUM(I17:I21) -> 5814.9458 | J22: =J12+J16+SUM(J17:J21) -> 6898.8735 | K22: =K12+K16+SUM(K17:K21) -> 8034.4489 | ... O22: =O12+O16+SUM(O17:O21) -> 12827.635
B24: Liabilities & equity
B25: Accounts payable | D25: 61.943 | E25: 130.453 | F25: =Assumptions!F115/365*-Inc_Stmt!F14 -> 228.06009 | G25: =Assumptions!G115/365*-Inc_Stmt!G14 -> 295.54786 | H25: =Assumptions!H115/365*-Inc_Stmt!H14 -> 352.03741 | I25: =Assumptions!I115/365*-Inc_Stmt!I14 -> 400.50685 | J25: =Assumptions!J115/365*-Inc_Stmt!J14 -> 441.38058 | K25: =Assumptions!K115/365*-Inc_Stmt!K14 -> 479.67934 | L25: =Assumptions!L115/365*-Inc_Stmt!L14 -> 513.42028 | M25: =Assumptions!M115/365*-Inc_Stmt!M14 -> 542.11822 | ... O25: =Assumptions!O115/365*-Inc_Stmt!O14 -> 585.857
B26: Accrued expenses | D26: 79.541 | E26: 122.356 | F26: =Assumptions!F125*Inc_Stmt!F12 -> 212.6071 | G26: =Assumptions!G125*Inc_Stmt!G12 -> 277.69147 | H26: =Assumptions!H125*Inc_Stmt!H12 -> 332.33814 | I26: =Assumptions!I125*Inc_Stmt!I12 -> 378.09533 | J26: =Assumptions!J125*Inc_Stmt!J12 -> 415.3674 | K26: =Assumptions!K125*Inc_Stmt!K12 -> 448.57884 | L26: =Assumptions!L125*Inc_Stmt!L12 -> 477.14067 | M26: =Assumptions!M125*Inc_Stmt!M12 -> 500.69117 | ... O26: =Assumptions!O125*Inc_Stmt!O12 -> 536.10823
B27: Payables pursuant to acquisitions | D27: 17.226 | E27: 0 | F27: 0 | G27: 0 | H27: 0 | I27: 0 | J27: 0 | K27: 0 | L27: 0 | M27: 0 | N27: 0 | O27: 0
B28: Customer deposits / deferred revenue | D28: 110.895 | E28: 263.859 | F28: =Assumptions!F130*Inc_Stmt!F12 -> 465.23436 | G28: =Assumptions!G130*Inc_Stmt!G12 -> 607.65428 | H28: =Assumptions!H130*Inc_Stmt!H12 -> 727.23404 | I28: =Assumptions!I130*Inc_Stmt!I12 -> 827.36155 | J28: =Assumptions!J130*Inc_Stmt!J12 -> 908.92161 | K28: =Assumptions!K130*Inc_Stmt!K12 -> 981.59604 | L28: =Assumptions!L130*Inc_Stmt!L12 -> 1044.0961 | M28: =Assumptions!M130*Inc_Stmt!M12 -> 1095.6301 | ... O28: =Assumptions!O130*Inc_Stmt!O12 -> 1173.131
B29: Operating lease liabilities, current | D29: 6.879 | E29: 8.626 | F29: =E29 -> 8.626 | G29: =F29 -> 8.626 | H29: =G29 -> 8.626 | I29: =H29 -> 8.626 | J29: =I29 -> 8.626 | K29: =J29 -> 8.626 | L29: =K29 -> 8.626 | M29: =L29 -> 8.626 | ... O29: =N29 -> 8.626
B30: Current portion of long-term debt | D30: 5.173 | E30: 6 | F30: =MIN(TLAmort,Capitalization!F18) -> 6 | G30: =MIN(TLAmort,Capitalization!G18) -> 6 | H30: =MIN(TLAmort,Capitalization!H18) -> 6 | I30: =MIN(TLAmort,Capitalization!I18) -> 6 | J30: =MIN(TLAmort,Capitalization!J18) -> 6 | K30: =MIN(TLAmort,Capitalization!K18) -> 6 | L30: =MIN(TLAmort,Capitalization!L18) -> 6 | M30: =MIN(TLAmort,Capitalization!M18) -> 6 | ... O30: =MIN(TLAmort,Capitalization!O18) -> 6
B31: Total current liabilities | D31: =SUM(D25:D30) -> 281.657 | E31: =SUM(E25:E30) -> 531.294 | F31: =SUM(F25:F30) -> 920.52755 | G31: =SUM(G25:G30) -> 1195.5196 | H31: =SUM(H25:H30) -> 1426.2356 | I31: =SUM(I25:I30) -> 1620.5897 | J31: =SUM(J25:J30) -> 1780.2956 | K31: =SUM(K25:K30) -> 1924.4802 | ... O31: =SUM(O25:O30) -> 2309.7222
B32: Long-term debt, net of discount | D32: 496.934 | E32: 576.175 | F32: =E30+E32-Capitalization!F17-F30 -> 570.175 | G32: =F30+F32-Capitalization!G17-G30 -> 564.175 | H32: =G30+G32-Capitalization!H17-H30 -> 558.175 | I32: =H30+H32-Capitalization!I17-I30 -> 552.175 | J32: =I30+I32-Capitalization!J17-J30 -> 546.175 | K32: =J30+J32-Capitalization!K17-K30 -> 540.175 | L32: =K30+K32-Capitalization!L17-L30 -> 534.175 | M32: =L30+L32-Capitalization!M17-M30 -> 528.175 | ... O32: =N30+N32-Capitalization!O17-O30 -> 516.175 | Q32: Carrying value: OID/fees ($16.3m) held flat; interest computed on principal
B33: Tax receivable agreement liability | D33: 0 | E33: 338.925 | F33: =E33 -> 338.925 | G33: =F33 -> 338.925 | H33: =G33 -> 338.925 | I33: =H33 -> 338.925 | J33: =I33 -> 338.925 | K33: =J33 -> 338.925 | L33: =K33 -> 338.925 | M33: =L33 -> 338.925 | ... O33: =N33 -> 338.925
B34: Deferred tax liabilities | D34: 63.318 | E34: 0 | F34: =E34 -> 0 | G34: =F34 -> 0 | H34: =G34 -> 0 | I34: =H34 -> 0 | J34: =I34 -> 0 | K34: =J34 -> 0 | L34: =K34 -> 0 | M34: =L34 -> 0 | ... O34: =N34 -> 0
B35: Operating lease liabilities, non-current | D35: 121.491 | E35: 112.97 | F35: =E35 -> 112.97 | G35: =F35 -> 112.97 | H35: =G35 -> 112.97 | I35: =H35 -> 112.97 | J35: =I35 -> 112.97 | K35: =J35 -> 112.97 | L35: =K35 -> 112.97 | M35: =L35 -> 112.97 | ... O35: =N35 -> 112.97
B36: Total liabilities | D36: =D31+SUM(D32:D35) -> 963.4 | E36: =E31+SUM(E32:E35) -> 1559.364 | F36: =F31+SUM(F32:F35) -> 1942.5975 | G36: =G31+SUM(G32:G35) -> 2211.5896 | H36: =H31+SUM(H32:H35) -> 2436.3056 | I36: =I31+SUM(I32:I35) -> 2624.6597 | J36: =J31+SUM(J32:J35) -> 2778.3656 | K36: =K31+SUM(K32:K35) -> 2916.5502 | ... O36: =O31+SUM(O32:O35) -> 3277.7922
B38: Total equity (incl. NCI) | D38: 573.286 | E38: 671.401 | F38: =E38+Inc_Stmt!F30+Inc_Stmt!F41 -> 1062.4648 | G38: =F38+Inc_Stmt!G30+Inc_Stmt!G41 -> 1631.1891 | H38: =G38+Inc_Stmt!H30+Inc_Stmt!H41 -> 2351.918 | I38: =H38+Inc_Stmt!I30+Inc_Stmt!I41 -> 3190.2861 | J38: =I38+Inc_Stmt!J30+Inc_Stmt!J41 -> 4120.5079 | K38: =J38+Inc_Stmt!K30+Inc_Stmt!K41 -> 5117.8987 | L38: =K38+Inc_Stmt!L30+Inc_Stmt!L41 -> 6170.0578 | M38: =L38+Inc_Stmt!M30+Inc_Stmt!M41 -> 7263.9575 | ... O38: =N38+Inc_Stmt!O30+Inc_Stmt!O41 -> 9549.8431 | Q38: Roll-forward: + net income + SBC (no dividends / buybacks / TRA payments modeled)
B40: Total liabilities & equity | D40: =D36+D38 -> 1536.686 | E40: =E36+E38 -> 2230.765 | F40: =F36+F38 -> 3005.0623 | G40: =G36+G38 -> 3842.7787 | H40: =H36+H38 -> 4788.2236 | I40: =I36+I38 -> 5814.9458 | J40: =J36+J38 -> 6898.8735 | K40: =K36+K38 -> 8034.4489 | ... O40: =O36+O38 -> 12827.635
B42: Balance check (assets − L&E) | D42: =ROUND(D22-D40,3) -> 0 | E42: =ROUND(E22-E40,3) -> 0 | F42: =ROUND(F22-F40,3) -> 0 | G42: =ROUND(G22-G40,3) -> 0 | H42: =ROUND(H22-H40,3) -> 0 | I42: =ROUND(I22-I40,3) -> 0 | J42: =ROUND(J22-J40,3) -> 0 | K42: =ROUND(K22-K40,3) -> 0 | ... O42: =ROUND(O22-O40,3) -> 0

Sheet Cash_Flow
A1: ="Cash Flow Statement for "&Name -> Cash Flow Statement for Forgent Power Solutions, Inc.
A2: (Dollars in Millions unless stated)
C4: ="Historical — fiscal years ending "&TEXT(FYE,"mmmm d") -> Historical — fiscal years ending June 30 | F4: ="Projected — fiscal years ending "&TEXT(FYE,"mmmm d") -> Projected — fiscal years ending June 30
C5: n/a | D5: FY25A | E5: FY26A | F5: FY27E | G5: FY28E | H5: FY29E | I5: FY30E | J5: FY31E | K5: FY32E | L5: FY33E | M5: FY34E | N5: FY35E | O5: FY36E
B6: Cash flow from operations
B7: Net income (incl. NCI) | D7: 17.446 | E7: 106.035 | F7: =Inc_Stmt!F30 -> 371.05367 | G7: =Inc_Stmt!G30 -> 542.58864 | H7: =Inc_Stmt!H30 -> 689.45005 | I7: =Inc_Stmt!I30 -> 802.78264 | J7: =Inc_Stmt!J30 -> 891.1284 | K7: =Inc_Stmt!K30 -> 955.17163 | L7: =Inc_Stmt!L30 -> 1007.2518 | M7: =Inc_Stmt!M30 -> 1046.7758 | ... O7: =Inc_Stmt!O30 -> 1108.8054 | Q7: 10-K cash flow statement (XBRL)
B8: Depreciation & amortization | D8: 64.864 | E8: 66.899 | F8: =Inc_Stmt!F39 -> 56.03355 | G8: =Inc_Stmt!G39 -> 64.237907 | H8: =Inc_Stmt!H39 -> 63.445847 | I8: =Inc_Stmt!I39 -> 63.776047 | J8: =Inc_Stmt!J39 -> 66.977269 | K8: =Inc_Stmt!K39 -> 71.352148 | L8: =Inc_Stmt!L39 -> 76.368449 | M8: =Inc_Stmt!M39 -> 83.419984 | ... O8: =Inc_Stmt!O39 -> 95.069136
B9: Amortization / write-off of debt costs | D9: 2.511 | E9: 12.987 | F9: 0 | G9: 0 | H9: 0 | I9: 0 | J9: 0 | K9: 0 | L9: 0 | M9: 0 | N9: 0 | O9: 0
B10: Deferred income taxes | D10: -15.733 | E10: 14.635 | F10: 0 | G10: 0 | H10: 0 | I10: 0 | J10: 0 | K10: 0 | L10: 0 | M10: 0 | N10: 0 | O10: 0
B11: Stock-based compensation | D11: 1.784 | E11: 10.036 | F11: =Inc_Stmt!F41 -> 20.01008 | G11: =Inc_Stmt!G41 -> 26.135668 | H11: =Inc_Stmt!H41 -> 31.278883 | I11: =Inc_Stmt!I41 -> 35.585443 | J11: =Inc_Stmt!J41 -> 39.093403 | K11: =Inc_Stmt!K41 -> 42.219185 | L11: =Inc_Stmt!L41 -> 44.907358 | M11: =Inc_Stmt!M41 -> 47.123875 | ... O11: =Inc_Stmt!O41 -> 50.457245
B12: Other non-cash items | D12: 8.153 | E12: 23.005 | F12: 0 | G12: 0 | H12: 0 | I12: 0 | J12: 0 | K12: 0 | L12: 0 | M12: 0 | N12: 0 | O12: 0 | Q12: Derived: reported CFO less all other listed lines (credit loss, inventory provisions, ROU amortization)
B14: (Increase) / decrease in A/R | D14: -78.51 | E14: -172.657 | F14: =-(Bal_Sht!F8-Bal_Sht!E8) -> -252.85721 | G14: =-(Bal_Sht!G8-Bal_Sht!F8) -> -178.31335 | H14: =-(Bal_Sht!H8-Bal_Sht!G8) -> -149.71689 | I14: =-(Bal_Sht!I8-Bal_Sht!H8) -> -125.36218 | J14: =-(Bal_Sht!J8-Bal_Sht!I8) -> -102.11526 | K14: =-(Bal_Sht!K8-Bal_Sht!J8) -> -90.990235 | L14: =-(Bal_Sht!L8-Bal_Sht!K8) -> -78.251609 | M14: =-(Bal_Sht!M8-Bal_Sht!L8) -> -64.521902 | ... O14: =-(Bal_Sht!O8-Bal_Sht!N8) -> -42.780282
B15: (Increase) / decrease in inventory | D15: -34.47 | E15: -142.909 | F15: =-(Bal_Sht!F9-Bal_Sht!E9) -> -184.37432 | G15: =-(Bal_Sht!G9-Bal_Sht!F9) -> -128.48634 | H15: =-(Bal_Sht!H9-Bal_Sht!G9) -> -107.5474 | I15: =-(Bal_Sht!I9-Bal_Sht!H9) -> -92.278364 | J15: =-(Bal_Sht!J9-Bal_Sht!I9) -> -77.817296 | K15: =-(Bal_Sht!K9-Bal_Sht!J9) -> -72.914946 | L15: =-(Bal_Sht!L9-Bal_Sht!K9) -> -64.237565 | M15: =-(Bal_Sht!M9-Bal_Sht!L9) -> -54.636455 | ... O15: =-(Bal_Sht!O9-Bal_Sht!N9) -> -35.808606
B16: (Increase) / decrease in prepaid & other | D16: -18.493 | E16: -66.465 | F16: =-(Bal_Sht!F10-Bal_Sht!E10) -> -88.17032 | G16: =-(Bal_Sht!G10-Bal_Sht!F10) -> -62.787277 | H16: =-(Bal_Sht!H10-Bal_Sht!G10) -> -52.717957 | I16: =-(Bal_Sht!I10-Bal_Sht!H10) -> -44.142236 | J16: =-(Bal_Sht!J10-Bal_Sht!I10) -> -35.956585 | K16: =-(Bal_Sht!K10-Bal_Sht!J10) -> -32.039267 | L16: =-(Bal_Sht!L10-Bal_Sht!K10) -> -27.553772 | M16: =-(Bal_Sht!M10-Bal_Sht!L10) -> -22.7193 | ... O16: =-(Bal_Sht!O10-Bal_Sht!N10) -> -15.063692
B17: Increase / (decrease) in A/P | D17: 35.183 | E17: 68.51 | F17: =Bal_Sht!F25-Bal_Sht!E25 -> 97.60709 | G17: =Bal_Sht!G25-Bal_Sht!F25 -> 67.487772 | H17: =Bal_Sht!H25-Bal_Sht!G25 -> 56.489543 | I17: =Bal_Sht!I25-Bal_Sht!H25 -> 48.469444 | J17: =Bal_Sht!J25-Bal_Sht!I25 -> 40.873731 | K17: =Bal_Sht!K25-Bal_Sht!J25 -> 38.298759 | L17: =Bal_Sht!L25-Bal_Sht!K25 -> 33.740943 | M17: =Bal_Sht!M25-Bal_Sht!L25 -> 28.697936 | ... O17: =Bal_Sht!O25-Bal_Sht!N25 -> 18.808561
B18: Increase / (decrease) in accrued expenses | D18: 44.481 | E18: 42.815 | F18: =Bal_Sht!F26-Bal_Sht!E26 -> 90.2511 | G18: =Bal_Sht!G26-Bal_Sht!F26 -> 65.084372 | H18: =Bal_Sht!H26-Bal_Sht!G26 -> 54.646663 | I18: =Bal_Sht!I26-Bal_Sht!H26 -> 45.757196 | J18: =Bal_Sht!J26-Bal_Sht!I26 -> 37.27207 | K18: =Bal_Sht!K26-Bal_Sht!J26 -> 33.211436 | L18: =Bal_Sht!L26-Bal_Sht!K26 -> 28.561837 | M18: =Bal_Sht!M26-Bal_Sht!L26 -> 23.550494 | ... O18: =Bal_Sht!O26-Bal_Sht!N26 -> 15.614803
B19: Increase / (decrease) in customer deposits | D19: 20.747 | E19: 152.964 | F19: =Bal_Sht!F28-Bal_Sht!E28 -> 201.37536 | G19: =Bal_Sht!G28-Bal_Sht!F28 -> 142.41992 | H19: =Bal_Sht!H28-Bal_Sht!G28 -> 119.57976 | I19: =Bal_Sht!I28-Bal_Sht!H28 -> 100.12751 | J19: =Bal_Sht!J28-Bal_Sht!I28 -> 81.560059 | K19: =Bal_Sht!K28-Bal_Sht!J28 -> 72.674436 | L19: =Bal_Sht!L28-Bal_Sht!K28 -> 62.50002 | M19: =Bal_Sht!M28-Bal_Sht!L28 -> 51.534023 | ... O19: =Bal_Sht!O28-Bal_Sht!N28 -> 34.168863
B20: Operating lease & other | D20: -2.941 | E20: -6.774 | F20: =(Bal_Sht!F29-Bal_Sht!E29)+(Bal_Sht!F35-Bal_Sht!E35)-(Bal_Sht!F17-Bal_Sht!E17) -> 0 | G20: =(Bal_Sht!G29-Bal_Sht!F29)+(Bal_Sht!G35-Bal_Sht!F35)-(Bal_Sht!G17-Bal_Sht!F17) -> 0 | H20: =(Bal_Sht!H29-Bal_Sht!G29)+(Bal_Sht!H35-Bal_Sht!G35)-(Bal_Sht!H17-Bal_Sht!G17) -> 0 | I20: =(Bal_Sht!I29-Bal_Sht!H29)+(Bal_Sht!I35-Bal_Sht!H35)-(Bal_Sht!I17-Bal_Sht!H17) -> 0 | J20: =(Bal_Sht!J29-Bal_Sht!I29)+(Bal_Sht!J35-Bal_Sht!I35)-(Bal_Sht!J17-Bal_Sht!I17) -> 0 | K20: =(Bal_Sht!K29-Bal_Sht!J29)+(Bal_Sht!K35-Bal_Sht!J35)-(Bal_Sht!K17-Bal_Sht!J17) -> 0 | L20: =(Bal_Sht!L29-Bal_Sht!K29)+(Bal_Sht!L35-Bal_Sht!K35)-(Bal_Sht!L17-Bal_Sht!K17) -> 0 | M20: =(Bal_Sht!M29-Bal_Sht!L29)+(Bal_Sht!M35-Bal_Sht!L35)-(Bal_Sht!M17-Bal_Sht!L17) -> 0 | ... O20: =(Bal_Sht!O29-Bal_Sht!N29)+(Bal_Sht!O35-Bal_Sht!N35)-(Bal_Sht!O17-Bal_Sht!N17) -> 0
B21: Total change in working capital | D21: =SUM(D14:D20) -> -34.003 | E21: =SUM(E14:E20) -> -124.516 | F21: =SUM(F14:F20) -> -136.1683 | G21: =SUM(G14:G20) -> -94.594896 | H21: =SUM(H14:H20) -> -79.266279 | I21: =SUM(I14:I20) -> -67.42863 | J21: =SUM(J14:J20) -> -56.183281 | K21: =SUM(K14:K20) -> -51.759817 | ... O21: =SUM(O14:O20) -> -25.060354
B23: Cash from operations | D23: =SUM(D7:D12)+D21 -> 45.022 | E23: =SUM(E7:E12)+E21 -> 109.081 | F23: =SUM(F7:F12)+F21 -> 310.929 | G23: =SUM(G7:G12)+G21 -> 538.36732 | H23: =SUM(H7:H12)+H21 -> 704.9085 | I23: =SUM(I7:I12)+I21 -> 834.7155 | J23: =SUM(J7:J12)+J21 -> 941.01579 | K23: =SUM(K7:K12)+K21 -> 1016.9831 | ... O23: =SUM(O7:O12)+O21 -> 1229.2714
B24: Cash flow from investing
B25: Capital expenditures | D25: -84.115 | E25: -115.905 | F25: =Inc_Stmt!F44 -> -87.0126 | G25: =Inc_Stmt!G44 -> -39.203502 | H25: =Inc_Stmt!H44 -> -50.828185 | I25: =Inc_Stmt!I44 -> -62.274525 | J25: =Inc_Stmt!J44 -> -73.30013 | K25: =Inc_Stmt!K44 -> -81.951156 | L25: =Inc_Stmt!L44 -> -100.53568 | M25: =Inc_Stmt!M44 -> -101.82568 | ... O25: =Inc_Stmt!O44 -> -103.53737
B26: Acquisitions | D26: 0 | E26: 0 | F26: 0 | G26: 0 | H26: 0 | I26: 0 | J26: 0 | K26: 0 | L26: 0 | M26: 0 | N26: 0 | O26: 0
B27: Cash from investing | D27: =SUM(D25:D26) -> -84.115 | E27: =SUM(E25:E26) -> -115.905 | F27: =SUM(F25:F26) -> -87.0126 | G27: =SUM(G25:G26) -> -39.203502 | H27: =SUM(H25:H26) -> -50.828185 | I27: =SUM(I25:I26) -> -62.274525 | J27: =SUM(J25:J26) -> -73.30013 | K27: =SUM(K25:K26) -> -81.951156 | ... O27: =SUM(O25:O26) -> -103.53737
B28: Cash flow from financing
B29: Debt issued | D29: 0 | E29: 594 | F29: 0 | G29: 0 | H29: 0 | I29: 0 | J29: 0 | K29: 0 | L29: 0 | M29: 0 | N29: 0 | O29: 0
B30: Debt repaid | D30: -5.173 | E30: -512.61 | F30: =-Capitalization!F17 -> -6 | G30: =-Capitalization!G17 -> -6 | H30: =-Capitalization!H17 -> -6 | I30: =-Capitalization!I17 -> -6 | J30: =-Capitalization!J17 -> -6 | K30: =-Capitalization!K17 -> -6 | L30: =-Capitalization!L17 -> -6 | M30: =-Capitalization!M17 -> -6 | ... O30: =-Capitalization!O17 -> -6
B31: IPO / follow-on proceeds, net (primary) | D31: 0 | E31: 1524.9 | F31: 0 | G31: 0 | H31: 0 | I31: 0 | J31: 0 | K31: 0 | L31: 0 | M31: 0 | N31: 0 | O31: 0 | Q31: IPO $491.8m + Mar/Jun follow-ons $1,033.1m — 100% used to buy Opco units (no cash to FPS)
B32: Purchase of Opco units from Neos (use of proceeds) | D32: 0 | E32: -1524.9 | F32: 0 | G32: 0 | H32: 0 | I32: 0 | J32: 0 | K32: 0 | L32: 0 | M32: 0 | N32: 0 | O32: 0
B33: Distributions to members / NCI | D33: -13.269 | E33: -1.44 | F33: 0 | G33: 0 | H33: 0 | I33: 0 | J33: 0 | K33: 0 | L33: 0 | M33: 0 | N33: 0 | O33: 0
B34: Other financing (debt costs, earnout, offering costs, tax distr.) | D34: -17.539 | E34: -62.735 | F34: 0 | G34: 0 | H34: 0 | I34: 0 | J34: 0 | K34: 0 | L34: 0 | M34: 0 | N34: 0 | O34: 0 | Q34: FY26: financing costs 13.5, earnout 17.2, offering costs 23.5, tax distributions ~8.6
B35: Cash from financing | D35: =SUM(D29:D34) -> -35.981 | E35: =SUM(E29:E34) -> 17.215 | F35: =SUM(F29:F34) -> -6 | G35: =SUM(G29:G34) -> -6 | H35: =SUM(H29:H34) -> -6 | I35: =SUM(I29:I34) -> -6 | J35: =SUM(J29:J34) -> -6 | K35: =SUM(K29:K34) -> -6 | ... O35: =SUM(O29:O34) -> -6
B37: Net change in cash & restricted cash | D37: =D23+D27+D35 -> -75.074 | E37: =E23+E27+E35 -> 10.391 | F37: =F23+F27+F35 -> 217.9164 | G37: =G23+G27+G35 -> 493.16382 | H37: =H23+H27+H35 -> 648.08032 | I37: =I23+I27+I35 -> 766.44097 | J37: =J23+J27+J35 -> 861.71566 | K37: =K23+K27+K35 -> 929.03199 | ... O37: =O23+O27+O35 -> 1119.734
B38: Beginning cash & restricted cash | D38: 186.396 | E38: =D39 -> 111.322 | F38: =E39 -> 121.713 | G38: =F39 -> 339.6294 | H38: =G39 -> 832.79322 | I38: =H39 -> 1480.8735 | J38: =I39 -> 2247.3145 | K38: =J39 -> 3109.0302 | L38: =K39 -> 4038.0622 | ... O38: =N39 -> 7120.5114 | Q38: FY25 beginning = FY25 ending $111.3m + $75.1m decrease
B39: Ending cash & restricted cash | D39: =D38+D37 -> 111.322 | E39: =E38+E37 -> 121.713 | F39: =F38+F37 -> 339.6294 | G39: =G38+G37 -> 832.79322 | H39: =H38+H37 -> 1480.8735 | I39: =I38+I37 -> 2247.3145 | J39: =J38+J37 -> 3109.0302 | K39: =K38+K37 -> 4038.0622 | ... O39: =O38+O37 -> 8240.2455
B40: Less: restricted cash (TRA) | D40: =-Bal_Sht!D11 -> 0 | E40: =-Bal_Sht!E11 -> -24.236 | F40: =-Bal_Sht!F11 -> -24.236 | G40: =-Bal_Sht!G11 -> -24.236 | H40: =-Bal_Sht!H11 -> -24.236 | I40: =-Bal_Sht!I11 -> -24.236 | J40: =-Bal_Sht!J11 -> -24.236 | K40: =-Bal_Sht!K11 -> -24.236 | ... O40: =-Bal_Sht!O11 -> -24.236
B41: Ending cash & equivalents (to balance sheet) | D41: =D39+D40 -> 111.322 | E41: =E39+E40 -> 97.477 | F41: =F39+F40 -> 315.3934 | G41: =G39+G40 -> 808.55722 | H41: =H39+H40 -> 1456.6375 | I41: =I39+I40 -> 2223.0785 | J41: =J39+J40 -> 3084.7942 | K41: =K39+K40 -> 4013.8262 | ... O41: =O39+O40 -> 8216.0095
B43: Supplemental
B44: Cash interest paid | D44: 54.605 | E44: 48.163 | F44: =-Inc_Stmt!F22 -> 38.24415 | G44: =-Inc_Stmt!G22 -> 37.86075 | H44: =-Inc_Stmt!H22 -> 37.47735 | I44: =-Inc_Stmt!I22 -> 37.09395 | J44: =-Inc_Stmt!J22 -> 36.71055 | K44: =-Inc_Stmt!K22 -> 36.32715 | L44: =-Inc_Stmt!L22 -> 35.94375 | M44: =-Inc_Stmt!M22 -> 35.56035 | ... O44: =-Inc_Stmt!O22 -> 34.79355
B45: Cash taxes paid | D45: 7.392 | E45: 13.687 | F45: =-Inc_Stmt!F28 -> 123.68456 | G45: =-Inc_Stmt!G28 -> 180.86288 | H45: =-Inc_Stmt!H28 -> 229.81668 | I45: =-Inc_Stmt!I28 -> 267.59421 | J45: =-Inc_Stmt!J28 -> 297.0428 | K45: =-Inc_Stmt!K28 -> 318.39054 | L45: =-Inc_Stmt!L28 -> 335.75059 | M45: =-Inc_Stmt!M28 -> 348.92528 | ... O45: =-Inc_Stmt!O28 -> 369.60179
...

Sheet WACC
A1: ="WACC Calculation for "&Name -> WACC Calculation for Forgent Power Solutions, Inc.
A2: (Dollars in Millions unless stated)
B3: WACC Calculation
B4: Cost of equity
B5: Risk-free rate (10Y UST) | D5: 0.0517 | F5: US Treasury daily par yield, 9/25/2026 (FRED DGS10 5.18% on 9/24)
B6: Equity risk premium | D6: 0.0414 | F6: Damodaran implied ERP, 9/1/2026 update (computed vs 4.75% Rf — rates rose since; see note)
B7: =Ticker&" beta (relevered peer median)" -> FPS beta (relevered peer median) | D7: =beta -> 1.1673281
B8: Size / company-specific premium | D8: 0
B9: Cost of equity | D9: =D5+D6*D7+D8 -> 0.10002738
B11: Cost of debt
B12: Pre-tax cost of debt (WACD) | D12: =Kd -> 0.0639
B13: Tax rate | D13: =TaxRate -> 0.25
B14: After-tax cost of debt | D14: =D12*(1-D13) -> 0.047925
B16: Capital structure (market value)
B17: Equity value | D17: =marketcap -> 11863.594
B18: Debt | D18: =totaldebt -> 598.5
B19: E / V | D19: =D17/SUM(D17:D18) -> 0.95197436
B20: D / V | D20: =D18/SUM(D17:D18) -> 0.048025638
B21: D / E | D21: =D18/D17 -> 0.050448457
B23: WACC | D23: =D9*D19+D14*D20 -> 0.097525133
B26: Peer beta relevering
B27: Company | C27: Levered β | D27: Market cap | E27: Total debt | F27: D / E | G27: Tax | H27: Unlevered β
B28: Eaton (ETN) | C28: 1.17 | D28: ='Financial Data'!F8 -> 170888.23 | E28: ='Financial Data'!G8 -> 21326 | F28: =E28/D28 -> 0.12479502 | G28: =TaxRate -> 0.25 | H28: =C28/(1+(1-G28)*F28) -> 1.0698647 | I28: Levered β: StockAnalysis 'Beta (5Y)' vs S&P 500, as of 9/25/2026 (Finviz within ±0.05)
B29: Vertiv (VRT) | C29: 2.07 | D29: ='Financial Data'!F9 -> 97510.267 | E29: ='Financial Data'!G9 -> 3338 | F29: =E29/D29 -> 0.034232293 | G29: =TaxRate -> 0.25 | H29: =C29/(1+(1-G29)*F29) -> 2.0181847
B30: Hubbell (HUBB) | C30: 0.89 | D30: ='Financial Data'!F10 -> 24651.535 | E30: ='Financial Data'!G10 -> 5557 | F30: =E30/D30 -> 0.22542207 | G30: =TaxRate -> 0.25 | H30: =C30/(1+(1-G30)*F30) -> 0.76129113
B31: nVent (NVT) | C31: 1.35 | D31: ='Financial Data'!F11 -> 26611.403 | E31: ='Financial Data'!G11 -> 1633 | F31: =E31/D31 -> 0.061364672 | G31: =TaxRate -> 0.25 | H31: =C31/(1+(1-G31)*F31) -> 1.290602
B32: GE Vernova (GEV) | C32: 0.97 | D32: ='Financial Data'!F12 -> 255045.6 | E32: ='Financial Data'!G12 -> 3720 | F32: =E32/D32 -> 0.014585627 | G32: =TaxRate -> 0.25 | H32: =C32/(1+(1-G32)*F32) -> 0.95950378 | I32: GEV: ~2.5 yrs of trading history
B33: Powell Industries (POWL) | C33: 1.18 | D33: ='Financial Data'!F13 -> 6904.5779 | E33: ='Financial Data'!G13 -> 2.52 | F33: =E33/D33 -> 0.00036497524 | G33: =TaxRate -> 0.25 | H33: =C33/(1+(1-G33)*F33) -> 1.1796771
B34: Median unlevered beta | H34: =MEDIAN(H28:H33) -> 1.1247709
B35: =Ticker&" target D / E" -> FPS target D / E | H35: =D21 -> 0.050448457
B36: Relevered beta | D36: =H34*(1+(1-TaxRate)*H35) -> 1.1673281
B38: Note: Damodaran's 4.14% implied ERP was computed against a 4.75% Rf; the 10Y has since risen to 5.17%. Pairing them mixes dates — flex D6 (e.g., 4.5%) to test.

Sheet Capitalization
A1: ="Debt Capitalization for "&Name -> Debt Capitalization for Forgent Power Solutions, Inc.
A2: (Dollars in Millions unless stated)
B4: Debt instrument | D4: Amount | F4: Maturity | H4: Rate | I4: Wtd. rate
B5: Term Loan B (Term SOFR + 2.25%) | D5: 598.5 | F5: 48567 | H5: 0.0639 | I5: =IF(CapDebt=0,0,D5/CapDebt*H5) -> 0.0639 | K5: 10-K Note 10: $598.5m principal, matures 12/19/2032, effective rate 6.39% at 6/30/26 (repriced 6/23/26)
B6: Revolver ($250m commitment, undrawn) | D6: 0 | F6: 47836 | H6: 0.0639 | I6: =IF(CapDebt=0,0,D6/CapDebt*H6) -> 0 | K6: 10-K Note 10: $246.4m available at 6/30/26 (LCs outstanding)
B8: Total debt | D8: =SUM(D5:D6) -> 598.5 | F8: WACD | H8: =SUM(I5:I6) -> 0.0639
B10: Memo — excluded from debt
B11: Operating lease liabilities | D11: 121.596 | K11: US GAAP operating lease cost sits inside EBITDA/EBIT, so leases are NOT treated as debt (avoids double count)
B12: TRA liability (in bridge, net of DTA & restricted cash) | D12: =TRA -> 338.925
B13: Mandatory amortization ($MM / yr) | D13: 6 | K13: 1% of original $600m per year (10-K maturities table: $6.0m FY27–FY31)
B15: Debt & Interest Schedule | F15: FY27E | G15: FY28E | H15: FY29E | I15: FY30E | J15: FY31E | K15: FY32E | L15: FY33E | M15: FY34E | N15: FY35E | O15: FY36E
B16: Term loan — beginning balance | F16: =$D$5 -> 598.5 | G16: =F18 -> 592.5 | H16: =G18 -> 586.5 | I16: =H18 -> 580.5 | J16: =I18 -> 574.5 | K16: =J18 -> 568.5 | L16: =K18 -> 562.5 | M16: =L18 -> 556.5 | N16: =M18 -> 550.5 | O16: =N18 -> 544.5
B17: Mandatory repayment | F17: =MIN(TLAmort,F16) -> 6 | G17: =MIN(TLAmort,G16) -> 6 | H17: =MIN(TLAmort,H16) -> 6 | I17: =MIN(TLAmort,I16) -> 6 | J17: =MIN(TLAmort,J16) -> 6 | K17: =MIN(TLAmort,K16) -> 6 | L17: =MIN(TLAmort,L16) -> 6 | M17: =MIN(TLAmort,M16) -> 6 | ... O17: =MIN(TLAmort,O16) -> 6
B18: Term loan — ending balance | F18: =F16-F17 -> 592.5 | G18: =G16-G17 -> 586.5 | H18: =H16-H17 -> 580.5 | I18: =I16-I17 -> 574.5 | J18: =J16-J17 -> 568.5 | K18: =K16-K17 -> 562.5 | L18: =L16-L17 -> 556.5 | M18: =M16-M17 -> 550.5 | ... O18: =O16-O17 -> 538.5
B19: Term loan interest (beginning bal. x rate) | F19: =F16*$H$5 -> 38.24415 | G19: =G16*$H$5 -> 37.86075 | H19: =H16*$H$5 -> 37.47735 | I19: =I16*$H$5 -> 37.09395 | J19: =J16*$H$5 -> 36.71055 | K19: =K16*$H$5 -> 36.32715 | L19: =L16*$H$5 -> 35.94375 | M19: =M16*$H$5 -> 35.56035 | ... O19: =O16*$H$5 -> 34.79355
B20: Revolver balance | F20: =$D$6 -> 0 | G20: =$D$6 -> 0 | H20: =$D$6 -> 0 | I20: =$D$6 -> 0 | J20: =$D$6 -> 0 | K20: =$D$6 -> 0 | L20: =$D$6 -> 0 | M20: =$D$6 -> 0 | ... O20: =$D$6 -> 0
B21: Revolver interest | F21: =F20*$H$6 -> 0 | G21: =G20*$H$6 -> 0 | H21: =H20*$H$6 -> 0 | I21: =I20*$H$6 -> 0 | J21: =J20*$H$6 -> 0 | K21: =K20*$H$6 -> 0 | L21: =L20*$H$6 -> 0 | M21: =M20*$H$6 -> 0 | ... O21: =O20*$H$6 -> 0
B22: Total interest expense | F22: =F19+F21 -> 38.24415 | G22: =G19+G21 -> 37.86075 | H22: =H19+H21 -> 37.47735 | I22: =I19+I21 -> 37.09395 | J22: =J19+J21 -> 36.71055 | K22: =K19+K21 -> 36.32715 | L22: =L19+L21 -> 35.94375 | M22: =M19+M21 -> 35.56035 | ... O22: =O19+O21 -> 34.79355
B24: Term loan matures 12/19/2032 (FY33). Model assumes refinancing on the same terms with 1% amortization continuing; floating rate — each ±100bp moves interest ~$6m/yr (10-K Item 7A).
B25: Undrawn revolver commitment fees and OID amortization are excluded (immaterial to UFCF).

Sheet DCF
A1: ="Discounted Cash Flows for "&Name -> Discounted Cash Flows for Forgent Power Solutions, Inc.
A2: (Dollars in Millions unless stated)
B3: Year # | F3: 1 | G3: 2 | H3: 3 | I3: 4 | J3: 5 | K3: 6 | L3: 7 | M3: 8 | N3: 9 | O3: 10
F4: ="Projected — fiscal years ending "&TEXT(FYE,"mmmm d") -> Projected — fiscal years ending June 30
