Workbook

Sheet Cover
A1: Forgent Power Solutions, Inc. (NYSE: FPS) - Valuation Model
A3: DCF (10-year, FY27E-FY36E, Base/Bull/Bear), trading comparables, precedent transactions, football-field summary.
A5: SHEETS
A6: Inputs - market data, capital structure, scenario drivers (scenario switch in yellow). Edit blue cells only.
A7: Historicals - FY25A/FY26A and FY26 quarters from the FY2026 10-K and Q4 earnings release.
A8: WACC - CAPM cost of equity with peer-based beta; optional override cell.
A9: DCF - unlevered FCF build, perpetuity-growth and exit-multiple terminal values, equity bridge.
A10: Sensitivity - share price vs WACC x terminal growth and WACC x exit multiple (live formulas).
A11: Comps - peer trading multiples with 25th/median/75th percentile implied FPS values.
A12: Precedents - M&A multiples for power-distribution / data-center power targets.
A13: Summary - football field across methods.
A15: KEY MODELLING CHOICES
... A25: Not investment advice. Peer and deal data are compiled from public sources and should be re-verified before use.

Sheet Inputs
A1: Forgent Power Solutions (NYSE: FPS) - Key Inputs & Scenario Assumptions
A2: $ in millions except per-share. Fiscal year ends June 30. Blue = hardcoded input; black = formula; green = link to another sheet; yellow = key lever.
A4: Market data & capital structure
A5: Valuation date | B5: 46290
A6: Share price ($) | B6: 38.97
A7: Class A shares outstanding (mm) | B7: 274.52709
A8: Class B shares / Opco units (mm) | B8: 29.901795
A9: Dilutive RSUs / options, treasury method (mm) | B9: 0.27
A10: Total debt - term loan ($mm) | B10: 582.175
A11: Cash & equivalents ($mm) | B11: 97.477
A12: Operating lease liabilities ($mm) - memo, not in bridge | B12: 121.596
A13: Fully diluted shares (mm) | B13: =B7+B8+B9
A14: Equity value / market cap ($mm) | B14: =B6*B13
A15: Net debt ($mm) | B15: =B10-B11
A16: Enterprise value at market ($mm) | B16: =B14+B15
A17: Note: TRA liability (Up-C tax receivable agreement) excluded from the bridge - see Cover note on tax treatment.
A19: Scenario selector
A20: Active case (1 = Base, 2 = Bull, 3 = Bear) | B20: 1 | C20: =CHOOSE(B20,"Base","Bull","Bear")
A22: Operating assumptions by scenario (FY27E = company guidance; FY28E+ = analyst assumption)
A23: Driver / case | B23: FY27E | C23: FY28E | D23: FY29E | E23: FY30E | F23: FY31E | G23: FY32E | H23: FY33E | I23: FY34E | J23: FY35E | K23: FY36E
A24: Base: revenue growth (FY27E cell = revenue $mm) | B24: 2500 | C24: 0.35 | D24: 0.2 | E24: 0.12 | F24: 0.08 | G24: 0.07 | H24: 0.06 | I24: 0.05 | J24: 0.04 | K24: 0.035
A25: Base: adj. EBITDA margin | B25: 0.24 | C25: 0.245 | D25: 0.245 | E25: 0.24 | F25: 0.235 | G25: 0.23 | H25: 0.225 | I25: 0.22 | J25: 0.22 | K25: 0.22
A26: Bull: revenue growth (FY27E cell = revenue $mm) | B26: 2600 | C26: 0.45 | D26: 0.28 | E26: 0.16 | F26: 0.1 | G26: 0.08 | H26: 0.07 | I26: 0.06 | J26: 0.05 | K26: 0.04
A27: Bull: adj. EBITDA margin | B27: 0.24 | C27: 0.255 | D27: 0.26 | E27: 0.26 | F27: 0.255 | G27: 0.25 | H27: 0.245 | I27: 0.24 | J27: 0.24 | K27: 0.24
A28: Bear: revenue growth (FY27E cell = revenue $mm) | B28: 2400 | C28: 0.15 | D28: 0.08 | E28: -0.05 | F28: 0.03 | G28: 0.04 | H28: 0.04 | I28: 0.035 | J28: 0.03 | K28: 0.03
A29: Bear: adj. EBITDA margin | B29: 0.24 | C29: 0.225 | D29: 0.21 | E29: 0.19 | F29: 0.18 | G29: 0.18 | H29: 0.18 | I29: 0.18 | J29: 0.18 | K29: 0.18
A30: Active: revenue growth / FY27E revenue | B30: =CHOOSE(Inputs!$B$20,B24,B26,B28) | C30: =CHOOSE(Inputs!$B$20,C24,C26,C28) | D30: =CHOOSE(Inputs!$B$20,D24,D26,D28) | E30: =CHOOSE(Inputs!$B$20,E24,E26,E28) | F30: =CHOOSE(Inputs!$B$20,F24,F26,F28) | G30: =CHOOSE(Inputs!$B$20,G24,G26,G28) | H30: =CHOOSE(Inputs!$B$20,H24,H26,H28) | I30: =CHOOSE(Inputs!$B$20,I24,I26,I28) | ... K30: =CHOOSE(Inputs!$B$20,K24,K26,K28)
A31: Active: adj. EBITDA margin | B31: =CHOOSE(Inputs!$B$20,B25,B27,B29) | C31: =CHOOSE(Inputs!$B$20,C25,C27,C29) | D31: =CHOOSE(Inputs!$B$20,D25,D27,D29) | E31: =CHOOSE(Inputs!$B$20,E25,E27,E29) | F31: =CHOOSE(Inputs!$B$20,F25,F27,F29) | G31: =CHOOSE(Inputs!$B$20,G25,G27,G29) | H31: =CHOOSE(Inputs!$B$20,H25,H27,H29) | I31: =CHOOSE(Inputs!$B$20,I25,I27,I29) | ... K31: =CHOOSE(Inputs!$B$20,K25,K27,K29)
A33: Other operating drivers (all cases)
A34: Driver | B34: FY27E | C34: FY28E | D34: FY29E | E34: FY30E | F34: FY31E | G34: FY32E | H34: FY33E | I34: FY34E | J34: FY35E | K34: FY36E
A35: Stock-based comp (% revenue) - treated as a cash cost | B35: 0.01 | C35: 0.01 | D35: 0.01 | E35: 0.01 | F35: 0.01 | G35: 0.01 | H35: 0.01 | I35: 0.01 | J35: 0.01 | K35: 0.01
A36: Depreciation (% revenue) | B36: 0.015 | C36: 0.016 | D36: 0.017 | E36: 0.018 | F36: 0.019 | G36: 0.02 | H36: 0.021 | I36: 0.022 | J36: 0.022 | K36: 0.022
A37: Capex (% revenue) | B37: 0.035 | C37: 0.035 | D37: 0.03 | E37: 0.03 | F37: 0.028 | G37: 0.026 | H37: 0.025 | I37: 0.025 | J37: 0.025 | K37: 0.025
A38: Change in NWC (% of change in revenue) | B38: 0.15 | C38: 0.15 | D38: 0.15 | E38: 0.15 | F38: 0.15 | G38: 0.15 | H38: 0.15 | I38: 0.15 | J38: 0.15 | K38: 0.15
A39: Cash tax rate on EBITA | B39: 0.25 | C39: 0.25 | D39: 0.25 | E39: 0.25 | F39: 0.25 | G39: 0.25 | H39: 0.25 | I39: 0.25 | J39: 0.25 | K39: 0.25
A41: Valuation inputs
A42: Terminal growth rate (perpetuity) | B42: 0.03
A43: Terminal EV / EBITDA exit multiple (cross-check) | B43: 14
A44: Mid-year convention (1 = on, 0 = off) | B44: 1
A45: Next fiscal year end | B45: 46568
...

Sheet Historicals
A1: Forgent - Historical Financials ($mm, FYE June 30)
A2: Source: FY2026 10-K and Q4 FY2026 earnings release (8-K, Sept 2026), SEC EDGAR CIK 0002080126. FY24 is a partial successor period after the Sept-2023 Neos Partners acquisition and is omitted.
A4: Income statement | B4: FY2025A | C4: FY2026A | D4: Q1 FY26A | E4: Q2 FY26A | F4: Q3 FY26A | G4: Q4 FY26A
A5: Revenue | B5: 753.188 | C5: 1420.059 | D5: 283.274 | E5: 296.404 | F5: 378.709 | G5: 461.672
A6: Gross profit | B6: 278.066 | C6: 497.6 | G6: 166.695
A7: SG&A | B7: 146.27 | C7: 262.886 | G7: 62.64
A8: Operating income | B8: 72.237 | C8: 182.489 | G8: 91.899
A9: Depreciation | B9: 6.188 | C9: 19.023 | G9: 5.623
A10: Amortization of intangibles | B10: 58.676 | C10: 47.876 | G10: 10.87
A11: Interest expense | B11: 54.778 | C11: 57.127 | G11: 11.423
A12: Income tax expense | B12: 5.34 | C12: 21.365 | G12: 14.427
A13: Net income | B13: 17.446 | C13: 106.035 | G13: 66.094
A14: Adjusted EBITDA (company definition) | B14: 169.173 | C14: 322.904 | F14: 85 | G14: 112.736
A15: Stock-based compensation | C15: 10.036 | G15: 4.49
A16: Capex | B16: 84.115 | C16: 115.905 | G16: 31
A17: Operating cash flow | B17: 45.022 | C17: 109.081 | G17: 74
A19: Ratios
A20: Revenue growth | C20: =C5/B5-1
A21: Gross margin | B21: =B6/B5 | C21: =C6/C5
A22: Adj. EBITDA margin | B22: =B14/B5 | C22: =C14/C5 | F22: =F14/F5 | G22: =G14/G5
A23: Capex % revenue | B23: =B16/B5 | C23: =C16/C5
A24: Depreciation % revenue | B24: =B9/B5 | C24: =C9/C5
A25: Free cash flow (OCF - capex) | B25: =B17-B16 | C25: =C17-C16
A27: Operating KPIs (30-Jun-2026)
A28: Backlog ($mm) | B28: 3000
A29: FY26 bookings ($mm) | B29: 1503
A30: FY26 revenue mix: Data center | B30: 0.59
A31: FY26 revenue mix: Grid | B31: 0.21
A32: FY26 revenue mix: Industrial | B32: 0.1
A33: FY26 revenue mix: Other | B33: 0.1
A34: Stated revenue capacity after Tijuana expansion ($mm) | B34: 5800

Sheet WACC
A1: Weighted Average Cost of Capital
A2: FPS listed Feb-2026: too little trading history for a reliable regression beta, so beta is peer-based.
A4: Risk-free rate (10-yr UST) | B4: 0.0425
A5: Equity risk premium | B5: 0.055
A6: Levered beta (peer-based) | B6: 1.45
A7: Size / company-specific premium | B7: 0
A8: Pre-tax cost of debt | B8: 0.0663
A9: Tax rate | B9: =Inputs!B39
A11: Cost of equity (CAPM) | B11: =B4+B6*B5+B7
A12: After-tax cost of debt | B12: =B8*(1-B9)
A14: Market value of equity ($mm) | B14: =Inputs!$B$14
A15: Debt ($mm) | B15: =Inputs!$B$10
A16: Debt / total capital | B16: =B15/(B14+B15)
A17: Equity / total capital | B17: =1-B16
A19: WACC | B19: =B17*B11+B16*B12
A20: WACC override (leave blank to use calculated)
A21: WACC used in DCF | B21: =IF(ISNUMBER(B20),B20,B19)

Sheet DCF
A1: Unlevered DCF - Forgent Power Solutions
A2: ="Active case: "&Inputs!$C$20&" | $mm, FYE June 30"
A4: ($mm) | B4: FY26A | C4: FY27E | D4: FY28E | E4: FY29E | F4: FY30E | G4: FY31E | H4: FY32E | I4: FY33E | J4: FY34E | K4: FY35E | L4: FY36E
A5: Revenue | B5: =Historicals!C5 | C5: =Inputs!B30 | D5: =C5*(1+D6) | E5: =D5*(1+E6) | F5: =E5*(1+F6) | G5: =F5*(1+G6) | H5: =G5*(1+H6) | I5: =H5*(1+I6) | J5: =I5*(1+J6) | K5: =J5*(1+K6) | L5: =K5*(1+L6)
A6: growth % | B6: =Historicals!C20 | C6: =C5/B5-1 | D6: =Inputs!C30 | E6: =Inputs!D30 | F6: =Inputs!E30 | G6: =Inputs!F30 | H6: =Inputs!G30 | I6: =Inputs!H30 | J6: =Inputs!I30 | K6: =Inputs!J30 | L6: =Inputs!K30
A7: Adj. EBITDA | B7: =Historicals!C14 | C7: =C5*C8 | D7: =D5*D8 | E7: =E5*E8 | F7: =F5*F8 | G7: =G5*G8 | H7: =H5*H8 | I7: =I5*I8 | J7: =J5*J8 | ... L7: =L5*L8
A8: margin % | B8: =B7/B5 | C8: =Inputs!B31 | D8: =Inputs!C31 | E8: =Inputs!D31 | F8: =Inputs!E31 | G8: =Inputs!F31 | H8: =Inputs!G31 | I8: =Inputs!H31 | J8: =Inputs!I31 | ... L8: =Inputs!K31
A9: (-) Stock-based comp | C9: =-C5*Inputs!B35 | D9: =-D5*Inputs!C35 | E9: =-E5*Inputs!D35 | F9: =-F5*Inputs!E35 | G9: =-G5*Inputs!F35 | H9: =-H5*Inputs!G35 | I9: =-I5*Inputs!H35 | J9: =-J5*Inputs!I35 | ... L9: =-L5*Inputs!K35
A10: (-) Depreciation | C10: =-C5*Inputs!B36 | D10: =-D5*Inputs!C36 | E10: =-E5*Inputs!D36 | F10: =-F5*Inputs!E36 | G10: =-G5*Inputs!F36 | H10: =-H5*Inputs!G36 | I10: =-I5*Inputs!H36 | J10: =-J5*Inputs!I36 | ... L10: =-L5*Inputs!K36
A11: EBITA (EBIT excl. acquired-intangible amortization) | C11: =C7+C9+C10 | D11: =D7+D9+D10 | E11: =E7+E9+E10 | F11: =F7+F9+F10 | G11: =G7+G9+G10 | H11: =H7+H9+H10 | I11: =I7+I9+I10 | J11: =J7+J9+J10 | ... L11: =L7+L9+L10
A12: (-) Cash taxes | C12: =-MAX(0,C11)*Inputs!B39 | D12: =-MAX(0,D11)*Inputs!C39 | E12: =-MAX(0,E11)*Inputs!D39 | F12: =-MAX(0,F11)*Inputs!E39 | G12: =-MAX(0,G11)*Inputs!F39 | H12: =-MAX(0,H11)*Inputs!G39 | I12: =-MAX(0,I11)*Inputs!H39 | J12: =-MAX(0,J11)*Inputs!I39 | ... L12: =-MAX(0,L11)*Inputs!K39
A13: NOPAT | C13: =C11+C12 | D13: =D11+D12 | E13: =E11+E12 | F13: =F11+F12 | G13: =G11+G12 | H13: =H11+H12 | I13: =I11+I12 | J13: =J11+J12 | ... L13: =L11+L12
A14: (+) Depreciation | C14: =-C10 | D14: =-D10 | E14: =-E10 | F14: =-F10 | G14: =-G10 | H14: =-H10 | I14: =-I10 | J14: =-J10 | ... L14: =-L10
A15: (-) Capex | C15: =-C5*Inputs!B37 | D15: =-D5*Inputs!C37 | E15: =-E5*Inputs!D37 | F15: =-F5*Inputs!E37 | G15: =-G5*Inputs!F37 | H15: =-H5*Inputs!G37 | I15: =-I5*Inputs!H37 | J15: =-J5*Inputs!I37 | ... L15: =-L5*Inputs!K37
A16: (-) Increase in NWC | C16: =-(C5-B5)*Inputs!B38 | D16: =-(D5-C5)*Inputs!C38 | E16: =-(E5-D5)*Inputs!D38 | F16: =-(F5-E5)*Inputs!E38 | G16: =-(G5-F5)*Inputs!F38 | H16: =-(H5-G5)*Inputs!G38 | I16: =-(I5-H5)*Inputs!H38 | J16: =-(J5-I5)*Inputs!I38 | ... L16: =-(L5-K5)*Inputs!K38
A17: Unlevered free cash flow | C17: =C13+C14+C15+C16 | D17: =D13+D14+D15+D16 | E17: =E13+E14+E15+E16 | F17: =F13+F14+F15+F16 | G17: =G13+G14+G15+G16 | H17: =H13+H14+H15+H16 | I17: =I13+I14+I15+I16 | J17: =J13+J14+J15+J16 | ... L17: =L13+L14+L15+L16
A18: UFCF margin % | C18: =C17/C5 | D18: =D17/D5 | E18: =E17/E5 | F18: =F17/F5 | G18: =G17/G5 | H18: =H17/H5 | I18: =I17/I5 | J18: =J17/J5 | ... L18: =L17/L5
A20: Fraction of year in forecast | C20: =Inputs!$B$46 | D20: 1 | E20: 1 | F20: 1 | G20: 1 | H20: 1 | I20: 1 | J20: 1 | K20: 1 | L20: 1
A21: Discount period (years) | C21: =SUM($C$20:C20)-Inputs!$B$44*C20/2 | D21: =SUM($C$20:D20)-Inputs!$B$44*D20/2 | E21: =SUM($C$20:E20)-Inputs!$B$44*E20/2 | F21: =SUM($C$20:F20)-Inputs!$B$44*F20/2 | G21: =SUM($C$20:G20)-Inputs!$B$44*G20/2 | H21: =SUM($C$20:H20)-Inputs!$B$44*H20/2 | I21: =SUM($C$20:I20)-Inputs!$B$44*I20/2 | J21: =SUM($C$20:J20)-Inputs!$B$44*J20/2 | ... L21: =SUM($C$20:L20)-Inputs!$B$44*L20/2
A22: Discount factor | C22: =1/(1+WACC!$B$21)^C21 | D22: =1/(1+WACC!$B$21)^D21 | E22: =1/(1+WACC!$B$21)^E21 | F22: =1/(1+WACC!$B$21)^F21 | G22: =1/(1+WACC!$B$21)^G21 | H22: =1/(1+WACC!$B$21)^H21 | I22: =1/(1+WACC!$B$21)^I21 | J22: =1/(1+WACC!$B$21)^J21 | ... L22: =1/(1+WACC!$B$21)^L21
A23: PV of UFCF | C23: =C17*C20*C22 | D23: =D17*D20*D22 | E23: =E17*E20*E22 | F23: =F17*F20*F22 | G23: =G17*G20*G22 | H23: =H17*H20*H22 | I23: =I17*I20*I22 | J23: =J17*J20*J22 | ... L23: =L17*L20*L22
A25: FY27E UFCF is pro-rated by the stub fraction (Q1 FY27 is already partly elapsed at the valuation date). Acquired-intangible amortization is excluded from EBITA; its tax shield is conservatively ignored.
A26: Valuation | B26: Perpetuity growth | C26: Exit multiple
A27: WACC | B27: =WACC!$B$21 | C27: =WACC!$B$21
A28: Terminal growth / exit EV/EBITDA | B28: =Inputs!$B$42 | C28: =Inputs!$B$43
A29: Terminal-year UFCF / EBITDA | B29: =L17 | C29: =L7
A30: Terminal value (at FY36 year-end) | B30: =B29*(1+B28)/(B27-B28) | C30: =C29*C28
A31: Discount period for TV (years) | B31: =SUM(C20:L20) | C31: =SUM(C20:L20)
A32: PV of terminal value | B32: =B30/(1+B27)^B31 | C32: =C30/(1+C27)^C31
A33: Sum of PV of UFCF | B33: =SUM(C23:L23) | C33: =SUM(C23:L23)
A34: Enterprise value | B34: =B32+B33 | C34: =C32+C33
A35: PV of TV as % of EV | B35: =B32/B34 | C35: =C32/C34
A36: (-) Debt | B36: =-Inputs!$B$10 | C36: =-Inputs!$B$10
A37: (+) Cash | B37: =Inputs!$B$11 | C37: =Inputs!$B$11
A38: Equity value | B38: =B34+B36+B37 | C38: =C34+C36+C37
A39: Fully diluted shares (mm) | B39: =Inputs!$B$13 | C39: =Inputs!$B$13
A40: Implied share price ($) | B40: =B38/B39 | C40: =C38/C39
A41: Current share price ($) | B41: =Inputs!$B$6 | C41: =Inputs!$B$6
A42: Upside / (downside) | B42: =B40/B41-1 | C42: =C40/C41-1
A43: Implied EV / FY27E EBITDA | B43: =B34/C7 | C43: =C34/C7
...

Sheet Sensitivity
A1: DCF Sensitivities - implied share price ($)
A2: Each cell recomputes the full DCF with SUMPRODUCT across the DCF sheet's UFCF row (active case).
A4: Perpetuity-growth method
A5: WACC \ terminal growth | C5: 0.02 | D5: 0.025 | E5: 0.03 | F5: 0.035 | G5: 0.04
B6: =WACC!$B$21+(-0.02) | C6: =(SUMPRODUCT(DCF!$C$17:$L$17,DCF!$C$20:$L$20,1/(1+$B6)^DCF!$C$21:$L$21)+(DCF!$L$17*(1+C$5)/($B6-C$5))/(1+$B6)^DCF!$B$31+(-Inputs!$B$10+Inputs!$B$11))/Inputs!$B$13 | D6: =(SUMPRODUCT(DCF!$C$17:$L$17,DCF!$C$20:$L$20,1/(1+$B6)^DCF!$C$21:$L$21)+(DCF!$L$17*(1+D$5)/($B6-D$5))/(1+$B6)^DCF!$B$31+(-Inputs!$B$10+Inputs!$B$11))/Inputs!$B$13 | E6: =(SUMPRODUCT(DCF!$C$17:$L$17,DCF!$C$20:$L$20,1/(1+$B6)^DCF!$C$21:$L$21)+(DCF!$L$17*(1+E$5)/($B6-E$5))/(1+$B6)^DCF!$B$31+(-Inputs!$B$10+Inputs!$B$11))/Inputs!$B$13 | F6: =(SUMPRODUCT(DCF!$C$17:$L$17,DCF!$C$20:$L$20,1/(1+$B6)^DCF!$C$21:$L$21)+(DCF!$L$17*(1+F$5)/($B6-F$5))/(1+$B6)^DCF!$B$31+(-Inputs!$B$10+Inputs!$B$11))/Inputs!$B$13 | G6: =(SUMPRODUCT(DCF!$C$17:$L$17,DCF!$C$20:$L$20,1/(1+$B6)^DCF!$C$21:$L$21)+(DCF!$L$17*(1+G$5)/($B6-G$5))/(1+$B6)^DCF!$B$31+(-Inputs!$B$10+Inputs!$B$11))/Inputs!$B$13
B7: =WACC!$B$21+(-0.01) | C7: =(SUMPRODUCT(DCF!$C$17:$L$17,DCF!$C$20:$L$20,1/(1+$B7)^DCF!$C$21:$L$21)+(DCF!$L$17*(1+C$5)/($B7-C$5))/(1+$B7)^DCF!$B$31+(-Inputs!$B$10+Inputs!$B$11))/Inputs!$B$13 | D7: =(SUMPRODUCT(DCF!$C$17:$L$17,DCF!$C$20:$L$20,1/(1+$B7)^DCF!$C$21:$L$21)+(DCF!$L$17*(1+D$5)/($B7-D$5))/(1+$B7)^DCF!$B$31+(-Inputs!$B$10+Inputs!$B$11))/Inputs!$B$13 | E7: =(SUMPRODUCT(DCF!$C$17:$L$17,DCF!$C$20:$L$20,1/(1+$B7)^DCF!$C$21:$L$21)+(DCF!$L$17*(1+E$5)/($B7-E$5))/(1+$B7)^DCF!$B$31+(-Inputs!$B$10+Inputs!$B$11))/Inputs!$B$13 | F7: =(SUMPRODUCT(DCF!$C$17:$L$17,DCF!$C$20:$L$20,1/(1+$B7)^DCF!$C$21:$L$21)+(DCF!$L$17*(1+F$5)/($B7-F$5))/(1+$B7)^DCF!$B$31+(-Inputs!$B$10+Inputs!$B$11))/Inputs!$B$13 | G7: =(SUMPRODUCT(DCF!$C$17:$L$17,DCF!$C$20:$L$20,1/(1+$B7)^DCF!$C$21:$L$21)+(DCF!$L$17*(1+G$5)/($B7-G$5))/(1+$B7)^DCF!$B$31+(-Inputs!$B$10+Inputs!$B$11))/Inputs!$B$13
B8: =WACC!$B$21+(0) | C8: =(SUMPRODUCT(DCF!$C$17:$L$17,DCF!$C$20:$L$20,1/(1+$B8)^DCF!$C$21:$L$21)+(DCF!$L$17*(1+C$5)/($B8-C$5))/(1+$B8)^DCF!$B$31+(-Inputs!$B$10+Inputs!$B$11))/Inputs!$B$13 | D8: =(SUMPRODUCT(DCF!$C$17:$L$17,DCF!$C$20:$L$20,1/(1+$B8)^DCF!$C$21:$L$21)+(DCF!$L$17*(1+D$5)/($B8-D$5))/(1+$B8)^DCF!$B$31+(-Inputs!$B$10+Inputs!$B$11))/Inputs!$B$13 | E8: =(SUMPRODUCT(DCF!$C$17:$L$17,DCF!$C$20:$L$20,1/(1+$B8)^DCF!$C$21:$L$21)+(DCF!$L$17*(1+E$5)/($B8-E$5))/(1+$B8)^DCF!$B$31+(-Inputs!$B$10+Inputs!$B$11))/Inputs!$B$13 | F8: =(SUMPRODUCT(DCF!$C$17:$L$17,DCF!$C$20:$L$20,1/(1+$B8)^DCF!$C$21:$L$21)+(DCF!$L$17*(1+F$5)/($B8-F$5))/(1+$B8)^DCF!$B$31+(-Inputs!$B$10+Inputs!$B$11))/Inputs!$B$13 | G8: =(SUMPRODUCT(DCF!$C$17:$L$17,DCF!$C$20:$L$20,1/(1+$B8)^DCF!$C$21:$L$21)+(DCF!$L$17*(1+G$5)/($B8-G$5))/(1+$B8)^DCF!$B$31+(-Inputs!$B$10+Inputs!$B$11))/Inputs!$B$13
B9: =WACC!$B$21+(0.01) | C9: =(SUMPRODUCT(DCF!$C$17:$L$17,DCF!$C$20:$L$20,1/(1+$B9)^DCF!$C$21:$L$21)+(DCF!$L$17*(1+C$5)/($B9-C$5))/(1+$B9)^DCF!$B$31+(-Inputs!$B$10+Inputs!$B$11))/Inputs!$B$13 | D9: =(SUMPRODUCT(DCF!$C$17:$L$17,DCF!$C$20:$L$20,1/(1+$B9)^DCF!$C$21:$L$21)+(DCF!$L$17*(1+D$5)/($B9-D$5))/(1+$B9)^DCF!$B$31+(-Inputs!$B$10+Inputs!$B$11))/Inputs!$B$13 | E9: =(SUMPRODUCT(DCF!$C$17:$L$17,DCF!$C$20:$L$20,1/(1+$B9)^DCF!$C$21:$L$21)+(DCF!$L$17*(1+E$5)/($B9-E$5))/(1+$B9)^DCF!$B$31+(-Inputs!$B$10+Inputs!$B$11))/Inputs!$B$13 | F9: =(SUMPRODUCT(DCF!$C$17:$L$17,DCF!$C$20:$L$20,1/(1+$B9)^DCF!$C$21:$L$21)+(DCF!$L$17*(1+F$5)/($B9-F$5))/(1+$B9)^DCF!$B$31+(-Inputs!$B$10+Inputs!$B$11))/Inputs!$B$13 | G9: =(SUMPRODUCT(DCF!$C$17:$L$17,DCF!$C$20:$L$20,1/(1+$B9)^DCF!$C$21:$L$21)+(DCF!$L$17*(1+G$5)/($B9-G$5))/(1+$B9)^DCF!$B$31+(-Inputs!$B$10+Inputs!$B$11))/Inputs!$B$13
B10: =WACC!$B$21+(0.02) | C10: =(SUMPRODUCT(DCF!$C$17:$L$17,DCF!$C$20:$L$20,1/(1+$B10)^DCF!$C$21:$L$21)+(DCF!$L$17*(1+C$5)/($B10-C$5))/(1+$B10)^DCF!$B$31+(-Inputs!$B$10+Inputs!$B$11))/Inputs!$B$13 | D10: =(SUMPRODUCT(DCF!$C$17:$L$17,DCF!$C$20:$L$20,1/(1+$B10)^DCF!$C$21:$L$21)+(DCF!$L$17*(1+D$5)/($B10-D$5))/(1+$B10)^DCF!$B$31+(-Inputs!$B$10+Inputs!$B$11))/Inputs!$B$13 | E10: =(SUMPRODUCT(DCF!$C$17:$L$17,DCF!$C$20:$L$20,1/(1+$B10)^DCF!$C$21:$L$21)+(DCF!$L$17*(1+E$5)/($B10-E$5))/(1+$B10)^DCF!$B$31+(-Inputs!$B$10+Inputs!$B$11))/Inputs!$B$13 | F10: =(SUMPRODUCT(DCF!$C$17:$L$17,DCF!$C$20:$L$20,1/(1+$B10)^DCF!$C$21:$L$21)+(DCF!$L$17*(1+F$5)/($B10-F$5))/(1+$B10)^DCF!$B$31+(-Inputs!$B$10+Inputs!$B$11))/Inputs!$B$13 | G10: =(SUMPRODUCT(DCF!$C$17:$L$17,DCF!$C$20:$L$20,1/(1+$B10)^DCF!$C$21:$L$21)+(DCF!$L$17*(1+G$5)/($B10-G$5))/(1+$B10)^DCF!$B$31+(-Inputs!$B$10+Inputs!$B$11))/Inputs!$B$13
A12: Exit-multiple method
A13: WACC \ exit multiple | C13: 10 | D13: 12 | E13: 14 | F13: 16 | G13: 18
B14: =WACC!$B$21+(-0.02) | C14: =(SUMPRODUCT(DCF!$C$17:$L$17,DCF!$C$20:$L$20,1/(1+$B14)^DCF!$C$21:$L$21)+(DCF!$L$7*C$13)/(1+$B14)^DCF!$B$31+(-Inputs!$B$10+Inputs!$B$11))/Inputs!$B$13 | D14: =(SUMPRODUCT(DCF!$C$17:$L$17,DCF!$C$20:$L$20,1/(1+$B14)^DCF!$C$21:$L$21)+(DCF!$L$7*D$13)/(1+$B14)^DCF!$B$31+(-Inputs!$B$10+Inputs!$B$11))/Inputs!$B$13 | E14: =(SUMPRODUCT(DCF!$C$17:$L$17,DCF!$C$20:$L$20,1/(1+$B14)^DCF!$C$21:$L$21)+(DCF!$L$7*E$13)/(1+$B14)^DCF!$B$31+(-Inputs!$B$10+Inputs!$B$11))/Inputs!$B$13 | F14: =(SUMPRODUCT(DCF!$C$17:$L$17,DCF!$C$20:$L$20,1/(1+$B14)^DCF!$C$21:$L$21)+(DCF!$L$7*F$13)/(1+$B14)^DCF!$B$31+(-Inputs!$B$10+Inputs!$B$11))/Inputs!$B$13 | G14: =(SUMPRODUCT(DCF!$C$17:$L$17,DCF!$C$20:$L$20,1/(1+$B14)^DCF!$C$21:$L$21)+(DCF!$L$7*G$13)/(1+$B14)^DCF!$B$31+(-Inputs!$B$10+Inputs!$B$11))/Inputs!$B$13
B15: =WACC!$B$21+(-0.01) | C15: =(SUMPRODUCT(DCF!$C$17:$L$17,DCF!$C$20:$L$20,1/(1+$B15)^DCF!$C$21:$L$21)+(DCF!$L$7*C$13)/(1+$B15)^DCF!$B$31+(-Inputs!$B$10+Inputs!$B$11))/Inputs!$B$13 | D15: =(SUMPRODUCT(DCF!$C$17:$L$17,DCF!$C$20:$L$20,1/(1+$B15)^DCF!$C$21:$L$21)+(DCF!$L$7*D$13)/(1+$B15)^DCF!$B$31+(-Inputs!$B$10+Inputs!$B$11))/Inputs!$B$13 | E15: =(SUMPRODUCT(DCF!$C$17:$L$17,DCF!$C$20:$L$20,1/(1+$B15)^DCF!$C$21:$L$21)+(DCF!$L$7*E$13)/(1+$B15)^DCF!$B$31+(-Inputs!$B$10+Inputs!$B$11))/Inputs!$B$13 | F15: =(SUMPRODUCT(DCF!$C$17:$L$17,DCF!$C$20:$L$20,1/(1+$B15)^DCF!$C$21:$L$21)+(DCF!$L$7*F$13)/(1+$B15)^DCF!$B$31+(-Inputs!$B$10+Inputs!$B$11))/Inputs!$B$13 | G15: =(SUMPRODUCT(DCF!$C$17:$L$17,DCF!$C$20:$L$20,1/(1+$B15)^DCF!$C$21:$L$21)+(DCF!$L$7*G$13)/(1+$B15)^DCF!$B$31+(-Inputs!$B$10+Inputs!$B$11))/Inputs!$B$13
B16: =WACC!$B$21+(0) | C16: =(SUMPRODUCT(DCF!$C$17:$L$17,DCF!$C$20:$L$20,1/(1+$B16)^DCF!$C$21:$L$21)+(DCF!$L$7*C$13)/(1+$B16)^DCF!$B$31+(-Inputs!$B$10+Inputs!$B$11))/Inputs!$B$13 | D16: =(SUMPRODUCT(DCF!$C$17:$L$17,DCF!$C$20:$L$20,1/(1+$B16)^DCF!$C$21:$L$21)+(DCF!$L$7*D$13)/(1+$B16)^DCF!$B$31+(-Inputs!$B$10+Inputs!$B$11))/Inputs!$B$13 | E16: =(SUMPRODUCT(DCF!$C$17:$L$17,DCF!$C$20:$L$20,1/(1+$B16)^DCF!$C$21:$L$21)+(DCF!$L$7*E$13)/(1+$B16)^DCF!$B$31+(-Inputs!$B$10+Inputs!$B$11))/Inputs!$B$13 | F16: =(SUMPRODUCT(DCF!$C$17:$L$17,DCF!$C$20:$L$20,1/(1+$B16)^DCF!$C$21:$L$21)+(DCF!$L$7*F$13)/(1+$B16)^DCF!$B$31+(-Inputs!$B$10+Inputs!$B$11))/Inputs!$B$13 | G16: =(SUMPRODUCT(DCF!$C$17:$L$17,DCF!$C$20:$L$20,1/(1+$B16)^DCF!$C$21:$L$21)+(DCF!$L$7*G$13)/(1+$B16)^DCF!$B$31+(-Inputs!$B$10+Inputs!$B$11))/Inputs!$B$13
B17: =WACC!$B$21+(0.01) | C17: =(SUMPRODUCT(DCF!$C$17:$L$17,DCF!$C$20:$L$20,1/(1+$B17)^DCF!$C$21:$L$21)+(DCF!$L$7*C$13)/(1+$B17)^DCF!$B$31+(-Inputs!$B$10+Inputs!$B$11))/Inputs!$B$13 | D17: =(SUMPRODUCT(DCF!$C$17:$L$17,DCF!$C$20:$L$20,1/(1+$B17)^DCF!$C$21:$L$21)+(DCF!$L$7*D$13)/(1+$B17)^DCF!$B$31+(-Inputs!$B$10+Inputs!$B$11))/Inputs!$B$13 | E17: =(SUMPRODUCT(DCF!$C$17:$L$17,DCF!$C$20:$L$20,1/(1+$B17)^DCF!$C$21:$L$21)+(DCF!$L$7*E$13)/(1+$B17)^DCF!$B$31+(-Inputs!$B$10+Inputs!$B$11))/Inputs!$B$13 | F17: =(SUMPRODUCT(DCF!$C$17:$L$17,DCF!$C$20:$L$20,1/(1+$B17)^DCF!$C$21:$L$21)+(DCF!$L$7*F$13)/(1+$B17)^DCF!$B$31+(-Inputs!$B$10+Inputs!$B$11))/Inputs!$B$13 | G17: =(SUMPRODUCT(DCF!$C$17:$L$17,DCF!$C$20:$L$20,1/(1+$B17)^DCF!$C$21:$L$21)+(DCF!$L$7*G$13)/(1+$B17)^DCF!$B$31+(-Inputs!$B$10+Inputs!$B$11))/Inputs!$B$13
B18: =WACC!$B$21+(0.02) | C18: =(SUMPRODUCT(DCF!$C$17:$L$17,DCF!$C$20:$L$20,1/(1+$B18)^DCF!$C$21:$L$21)+(DCF!$L$7*C$13)/(1+$B18)^DCF!$B$31+(-Inputs!$B$10+Inputs!$B$11))/Inputs!$B$13 | D18: =(SUMPRODUCT(DCF!$C$17:$L$17,DCF!$C$20:$L$20,1/(1+$B18)^DCF!$C$21:$L$21)+(DCF!$L$7*D$13)/(1+$B18)^DCF!$B$31+(-Inputs!$B$10+Inputs!$B$11))/Inputs!$B$13 | E18: =(SUMPRODUCT(DCF!$C$17:$L$17,DCF!$C$20:$L$20,1/(1+$B18)^DCF!$C$21:$L$21)+(DCF!$L$7*E$13)/(1+$B18)^DCF!$B$31+(-Inputs!$B$10+Inputs!$B$11))/Inputs!$B$13 | F18: =(SUMPRODUCT(DCF!$C$17:$L$17,DCF!$C$20:$L$20,1/(1+$B18)^DCF!$C$21:$L$21)+(DCF!$L$7*F$13)/(1+$B18)^DCF!$B$31+(-Inputs!$B$10+Inputs!$B$11))/Inputs!$B$13 | G18: =(SUMPRODUCT(DCF!$C$17:$L$17,DCF!$C$20:$L$20,1/(1+$B18)^DCF!$C$21:$L$21)+(DCF!$L$7*G$13)/(1+$B18)^DCF!$B$31+(-Inputs!$B$10+Inputs!$B$11))/Inputs!$B$13
A20: Base-case scenario table: flip Inputs!B20 (1/2/3) to see Bull / Bear on every sheet.

Sheet Comps
A1: Trading Comparables - Electrical / Power Infrastructure Equipment
A2: Market data as of 25-Sep-2026 close. $mm (local currency for non-US listings; multiples are currency-neutral). Consensus estimates are calendar-year. Blue = sourced input (see cell comments / notes below).
A4: Company | B4: Ticker | C4: Share price | D4: Diluted shares (mm) | E4: Market cap | F4: Debt | G4: Cash | H4: Enterprise value | I4: LTM revenue | J4: LTM EBITDA | K4: CY26E revenue | L4: CY27E revenue | M4: CY26E EBITDA | N4: CY27E EBITDA | O4: EV / LTM rev | P4: EV / CY26E rev | Q4: EV / LTM EBITDA | R4: EV / CY26E EBITDA | S4: EV / CY27E EBITDA | T4: CY26-27E rev growth | U4: CY26E EBITDA margin
A5: Vertiv | B5: VRT | C5: 253.28 | D5: 384.99 | E5: =C5*D5 | F5: 3340 | G5: 3110 | H5: =E5+F5-G5 | I5: 11480 | J5: 2680 | K5: 14019 | L5: 18239 | M5: 3488 | N5: 4817 | O5: =IF(ISNUMBER(I5),IF(I5>0,H5/I5,"n/m"),"n/a") | P5: =IF(ISNUMBER(K5),IF(K5>0,H5/K5,"n/m"),"n/a") | Q5: =IF(ISNUMBER(J5),IF(J5>0,H5/J5,"n/m"),"n/a") | R5: =IF(ISNUMBER(M5),IF(M5>0,H5/M5,"n/m"),"n/a") | S5: =IF(ISNUMBER(N5),IF(N5>0,H5/N5,"n/m"),"n/a") | T5: =IF(AND(ISNUMBER(K5),ISNUMBER(L5)),L5/K5-1,"n/a") | U5: =IF(AND(ISNUMBER(K5),ISNUMBER(M5)),M5/K5,"n/a")
A6: Eaton | B6: ETN | C6: 439.98 | D6: 388.4 | E6: =C6*D6 | F6: 21330 | G6: 695 | H6: =E6+F6-G6 | I6: 30030 | J6: 6640 | K6: 32683 | L6: 36626 | M6: 7754 | N6: 8991 | O6: =IF(ISNUMBER(I6),IF(I6>0,H6/I6,"n/m"),"n/a") | P6: =IF(ISNUMBER(K6),IF(K6>0,H6/K6,"n/m"),"n/a") | Q6: =IF(ISNUMBER(J6),IF(J6>0,H6/J6,"n/m"),"n/a") | R6: =IF(ISNUMBER(M6),IF(M6>0,H6/M6,"n/m"),"n/a") | S6: =IF(ISNUMBER(N6),IF(N6>0,H6/N6,"n/m"),"n/a") | T6: =IF(AND(ISNUMBER(K6),ISNUMBER(L6)),L6/K6-1,"n/a") | U6: =IF(AND(ISNUMBER(K6),ISNUMBER(M6)),M6/K6,"n/a")
A7: GE Vernova | B7: GEV | C7: 957.63 | D7: 266.33 | E7: =C7*D7 | F7: 3720 | G7: 12720 | H7: =E7+F7-G7 | I7: 41370 | J7: 3930 | K7: 46282 | L7: 52740 | M7: 6359 | N7: 9574 | O7: =IF(ISNUMBER(I7),IF(I7>0,H7/I7,"n/m"),"n/a") | P7: =IF(ISNUMBER(K7),IF(K7>0,H7/K7,"n/m"),"n/a") | Q7: =IF(ISNUMBER(J7),IF(J7>0,H7/J7,"n/m"),"n/a") | R7: =IF(ISNUMBER(M7),IF(M7>0,H7/M7,"n/m"),"n/a") | S7: =IF(ISNUMBER(N7),IF(N7>0,H7/N7,"n/m"),"n/a") | T7: =IF(AND(ISNUMBER(K7),ISNUMBER(L7)),L7/K7-1,"n/a") | U7: =IF(AND(ISNUMBER(K7),ISNUMBER(M7)),M7/K7,"n/a")
A8: Powell Industries (FYE Sep) | B8: POWL | C8: 189.53 | D8: 36.43 | E8: =C8*D8 | F8: 2.5 | G8: 633.6 | H8: =E8+F8-G8 | I8: 1160 | J8: 236.2 | K8: 1191 | L8: 1483 | M8: 244.1 | N8: 315 | O8: =IF(ISNUMBER(I8),IF(I8>0,H8/I8,"n/m"),"n/a") | P8: =IF(ISNUMBER(K8),IF(K8>0,H8/K8,"n/m"),"n/a") | Q8: =IF(ISNUMBER(J8),IF(J8>0,H8/J8,"n/m"),"n/a") | R8: =IF(ISNUMBER(M8),IF(M8>0,H8/M8,"n/m"),"n/a") | S8: =IF(ISNUMBER(N8),IF(N8>0,H8/N8,"n/m"),"n/a") | T8: =IF(AND(ISNUMBER(K8),ISNUMBER(L8)),L8/K8-1,"n/a") | U8: =IF(AND(ISNUMBER(K8),ISNUMBER(M8)),M8/K8,"n/a")
A9: Hubbell | B9: HUBB | C9: 466.62 | D9: 52.83 | E9: =C9*D9 | F9: 5560 | G9: 394.7 | H9: =E9+F9-G9 | I9: 6220 | J9: 1520 | K9: 6871 | L9: 7572 | M9: 1688 | N9: 1923 | O9: =IF(ISNUMBER(I9),IF(I9>0,H9/I9,"n/m"),"n/a") | P9: =IF(ISNUMBER(K9),IF(K9>0,H9/K9,"n/m"),"n/a") | Q9: =IF(ISNUMBER(J9),IF(J9>0,H9/J9,"n/m"),"n/a") | R9: =IF(ISNUMBER(M9),IF(M9>0,H9/M9,"n/m"),"n/a") | S9: =IF(ISNUMBER(N9),IF(N9>0,H9/N9,"n/m"),"n/a") | T9: =IF(AND(ISNUMBER(K9),ISNUMBER(L9)),L9/K9-1,"n/a") | U9: =IF(AND(ISNUMBER(K9),ISNUMBER(M9)),M9/K9,"n/a")
A10: nVent Electric | B10: NVT | C10: 164.41 | D10: 161.86 | E10: =C10*D10 | F10: 1630 | G10: 256 | H10: =E10+F10-G10 | I10: 4830 | J10: 1050 | K10: 5460 | L10: 6421 | M10: 1217 | N10: 1443 | O10: =IF(ISNUMBER(I10),IF(I10>0,H10/I10,"n/m"),"n/a") | P10: =IF(ISNUMBER(K10),IF(K10>0,H10/K10,"n/m"),"n/a") | Q10: =IF(ISNUMBER(J10),IF(J10>0,H10/J10,"n/m"),"n/a") | R10: =IF(ISNUMBER(M10),IF(M10>0,H10/M10,"n/m"),"n/a") | S10: =IF(ISNUMBER(N10),IF(N10>0,H10/N10,"n/m"),"n/a") | T10: =IF(AND(ISNUMBER(K10),ISNUMBER(L10)),L10/K10-1,"n/a") | U10: =IF(AND(ISNUMBER(K10),ISNUMBER(M10)),M10/K10,"n/a")
A11: Schneider Electric (EUR) | B11: SU FP | C11: 291 | D11: 562.33 | E11: =C11*D11 | F11: 20810 | G11: 4520 | H11: =E11+F11-G11 | I11: 42040 | J11: 8520 | K11: 44918 | L11: 49022 | M11: 9719 | N11: 11171 | O11: =IF(ISNUMBER(I11),IF(I11>0,H11/I11,"n/m"),"n/a") | P11: =IF(ISNUMBER(K11),IF(K11>0,H11/K11,"n/m"),"n/a") | Q11: =IF(ISNUMBER(J11),IF(J11>0,H11/J11,"n/m"),"n/a") | R11: =IF(ISNUMBER(M11),IF(M11>0,H11/M11,"n/m"),"n/a") | S11: =IF(ISNUMBER(N11),IF(N11>0,H11/N11,"n/m"),"n/a") | T11: =IF(AND(ISNUMBER(K11),ISNUMBER(L11)),L11/K11-1,"n/a") | U11: =IF(AND(ISNUMBER(K11),ISNUMBER(M11)),M11/K11,"n/a")
A12: Legrand (EUR) | B12: LR FP | C12: 134.85 | D12: 262.14 | E12: =C12*D12 | F12: 7720 | G12: 1970 | H12: =E12+F12-G12 | I12: 10110 | J12: 2220 | K12: 11031 | L12: 12193 | M12: 2622 | N12: 2939 | O12: =IF(ISNUMBER(I12),IF(I12>0,H12/I12,"n/m"),"n/a") | P12: =IF(ISNUMBER(K12),IF(K12>0,H12/K12,"n/m"),"n/a") | Q12: =IF(ISNUMBER(J12),IF(J12>0,H12/J12,"n/m"),"n/a") | R12: =IF(ISNUMBER(M12),IF(M12>0,H12/M12,"n/m"),"n/a") | S12: =IF(ISNUMBER(N12),IF(N12>0,H12/N12,"n/m"),"n/a") | T12: =IF(AND(ISNUMBER(K12),ISNUMBER(L12)),L12/K12-1,"n/a") | U12: =IF(AND(ISNUMBER(K12),ISNUMBER(M12)),M12/K12,"n/a")
A13: Hammond Power Solutions (CAD, pro forma AEG) | B13: HPS.A CN | C13: 279.22 | D13: 11.9 | E13: =C13*D13 | F13: 505 | G13: 33.63 | H13: =E13+F13-G13 | I13: 1060 | J13: n/a | K13: 1409 | L13: 1708 | M13: 215.5 | N13: 263 | O13: =IF(ISNUMBER(I13),IF(I13>0,H13/I13,"n/m"),"n/a") | P13: =IF(ISNUMBER(K13),IF(K13>0,H13/K13,"n/m"),"n/a") | Q13: =IF(ISNUMBER(J13),IF(J13>0,H13/J13,"n/m"),"n/a") | R13: =IF(ISNUMBER(M13),IF(M13>0,H13/M13,"n/m"),"n/a") | S13: =IF(ISNUMBER(N13),IF(N13>0,H13/N13,"n/m"),"n/a") | T13: =IF(AND(ISNUMBER(K13),ISNUMBER(L13)),L13/K13-1,"n/a") | U13: =IF(AND(ISNUMBER(K13),ISNUMBER(M13)),M13/K13,"n/a")
A15: Maximum | O15: =MAX(O5:O13) | P15: =MAX(P5:P13) | Q15: =MAX(Q5:Q13) | R15: =MAX(R5:R13) | S15: =MAX(S5:S13) | T15: =MAX(T5:T13) | U15: =MAX(U5:U13)
A16: 75th percentile | O16: =QUARTILE(O5:O13,3) | P16: =QUARTILE(P5:P13,3) | Q16: =QUARTILE(Q5:Q13,3) | R16: =QUARTILE(R5:R13,3) | S16: =QUARTILE(S5:S13,3) | T16: =QUARTILE(T5:T13,3) | U16: =QUARTILE(U5:U13,3)
A17: Mean | O17: =AVERAGE(O5:O13) | P17: =AVERAGE(P5:P13) | Q17: =AVERAGE(Q5:Q13) | R17: =AVERAGE(R5:R13) | S17: =AVERAGE(S5:S13) | T17: =AVERAGE(T5:T13) | U17: =AVERAGE(U5:U13)
A18: Median | O18: =MEDIAN(O5:O13) | P18: =MEDIAN(P5:P13) | Q18: =MEDIAN(Q5:Q13) | R18: =MEDIAN(R5:R13) | S18: =MEDIAN(S5:S13) | T18: =MEDIAN(T5:T13) | U18: =MEDIAN(U5:U13)
A19: 25th percentile | O19: =QUARTILE(O5:O13,1) | P19: =QUARTILE(P5:P13,1) | Q19: =QUARTILE(Q5:Q13,1) | R19: =QUARTILE(R5:R13,1) | S19: =QUARTILE(S5:S13,1) | T19: =QUARTILE(T5:T13,1) | U19: =QUARTILE(U5:U13,1)
A20: Minimum | O20: =MIN(O5:O13) | P20: =MIN(P5:P13) | Q20: =MIN(Q5:Q13) | R20: =MIN(R5:R13) | S20: =MIN(S5:S13) | T20: =MIN(T5:T13) | U20: =MIN(U5:U13)
A22: Forgent Power Solutions (at market) | B22: FPS | C22: =Inputs!$B$6 | D22: =Inputs!$B$13 | E22: =C22*D22 | F22: =Inputs!$B$10 | G22: =Inputs!$B$11 | H22: =E22+F22-G22 | I22: =Historicals!C5 | J22: =Historicals!C14 | K22: =0.5*Historicals!C5+0.5*DCF!C5 | L22: =0.5*DCF!C5+0.5*DCF!D5 | M22: =0.5*Historicals!C14+0.5*DCF!C7 | N22: =0.5*DCF!C7+0.5*DCF!D7 | O22: =H22/I22 | P22: =H22/K22 | Q22: =H22/J22 | R22: =H22/M22 | S22: =H22/N22 | T22: =L22/K22-1 | U22: =M22/K22
A25: Implied FPS valuation from peer multiples (25th percentile - median - 75th percentile)
A26: Metric | C26: FPS metric | D26: 25th pct | E26: Median | F26: 75th pct | G26: EV low | H26: EV mid | I26: EV high | J26: Price low | K26: Price mid | L26: Price high
A27: EV / CY26E EBITDA | C27: =M22 | D27: =R19 | E27: =R18 | F27: =R16 | G27: =$C27*D27 | H27: =$C27*E27 | I27: =$C27*F27 | J27: =(G27+(-Inputs!$B$10+Inputs!$B$11))/Inputs!$B$13 | K27: =(H27+(-Inputs!$B$10+Inputs!$B$11))/Inputs!$B$13 | L27: =(I27+(-Inputs!$B$10+Inputs!$B$11))/Inputs!$B$13
A28: EV / CY27E EBITDA | C28: =N22 | D28: =S19 | E28: =S18 | F28: =S16 | G28: =$C28*D28 | H28: =$C28*E28 | I28: =$C28*F28 | J28: =(G28+(-Inputs!$B$10+Inputs!$B$11))/Inputs!$B$13 | K28: =(H28+(-Inputs!$B$10+Inputs!$B$11))/Inputs!$B$13 | L28: =(I28+(-Inputs!$B$10+Inputs!$B$11))/Inputs!$B$13
A29: EV / LTM EBITDA | C29: =J22 | D29: =Q19 | E29: =Q18 | F29: =Q16 | G29: =$C29*D29 | H29: =$C29*E29 | I29: =$C29*F29 | J29: =(G29+(-Inputs!$B$10+Inputs!$B$11))/Inputs!$B$13 | K29: =(H29+(-Inputs!$B$10+Inputs!$B$11))/Inputs!$B$13 | L29: =(I29+(-Inputs!$B$10+Inputs!$B$11))/Inputs!$B$13
A31: Read-across caveat: FPS is guiding +76% revenue growth for FY27 vs. low-double-digit growth for most peers, so peer multiples on near-year EBITDA understate a growth-adjusted value; the CY27E multiple is the more relevant anchor. Conversely FPS carries higher customer concentration (~59% data center) and a short public track record.
A32: Notes: (1) LTM EBITDA is stockanalysis GAAP-basis, not company-adjusted; GE Vernova and Hammond LTM figures are distorted - prefer forward multiples.
A33: (2) Powell's fiscal year ends Sep; others calendar. FPS is calendarized from its June FYE (see cell comments).
A34: (3) Consensus from MarketScreener; the consensus date could not be confirmed on the page. FY26 revenue matched stockanalysis consensus as of 25-Sep-2026.
A35: (4) Excluded: ABB (market data CHF vs. estimates USD), Mitsubishi Electric (conglomerate), Siemens Energy (gas turbines/wind dominate mix).
A36: Sources: stockanalysis.com statistics pages; marketscreener.com /finances/ pages for each ticker; Hammond Q2-2026 release and AEG closing release (globenewswire, 29-Jun and 30-Jul-2026).

Sheet Precedents
A1: Precedent Transactions - Electrical Distribution & Data-Center Power Infrastructure
A2: $mm. Multiples on target LTM figures unless the Basis column says otherwise. Control premia are embedded; precedent values are therefore not directly comparable to a minority trading price.
A4: Announced | B4: Acquirer | C4: Target | D4: Target description | E4: Enterprise value | F4: Target revenue | G4: Target EBITDA | H4: EV / revenue | I4: EV / EBITDA | J4: Basis / notes | K4: In stats (1/0) | L4: EV/rev (stats) | M4: EV/EBITDA (stats)
A5: Sep-2026 | B5: Flex | C5: EPC Power | D5: Power conversion (rectifiers, DC-DC, SSTs) for data centers and grid | E5: 4400 | F5: 800 | G5: 336 | H5: =IF(ISNUMBER(F5),E5/F5,"n/a") | I5: =IF(ISNUMBER(G5),E5/G5,"n/a") | J5: Rev 2026E; EBITDA 2027E derived (~40% growth, ~30% margin) | K5: 1 | L5: =IF(AND(K5=1,ISNUMBER(H5)),H5,"") | M5: =IF(AND(K5=1,ISNUMBER(I5)),I5,"")
A6: Sep-2026 | B6: Vertiv | C6: UtilityInnovation Group | D6: Microgrid switchgear and power controls for data centers | E6: 1450 | F6: n/a | G6: 112 | H6: =IF(ISNUMBER(F6),E6/F6,"n/a") | I6: =IF(ISNUMBER(G6),E6/G6,"n/a") | J6: 2027E EBITDA; ~13x stated; excludes up to $1.15bn earnout | K6: 1 | L6: =IF(AND(K6=1,ISNUMBER(H6)),H6,"") | M6: =IF(AND(K6=1,ISNUMBER(I6)),I6,"")
A7: Mar-2026 | B7: Flex | C7: Electrical Power Products (EP2) | D7: Engineered control/relay panels, modular control buildings | E7: 1100 | F7: 323 | G7: n/a | H7: =IF(ISNUMBER(F7),E7/F7,"n/a") | I7: =IF(ISNUMBER(G7),E7/G7,"n/a") | J7: Rev FY Mar-26; EBITDA not disclosed; ~$100mm tax benefit | K7: 1 | L7: =IF(AND(K7=1,ISNUMBER(H7)),H7,"") | M7: =IF(AND(K7=1,ISNUMBER(I7)),I7,"")
A8: Oct-2025 | B8: GE Vernova | C8: Prolec GE (remaining 50%) | D8: Power, distribution and specialty transformers (North America) | E8: 10550 | F8: 3000 | G8: 750 | H8: =IF(ISNUMBER(F8),E8/F8,"n/a") | I8: =IF(ISNUMBER(G8),E8/G8,"n/a") | J8: 2025E; 50% stake price ($5.275bn) scaled to 100%; EBITDA derived at ~25% margin | K8: 1 | L8: =IF(AND(K8=1,ISNUMBER(H8)),H8,"") | M8: =IF(AND(K8=1,ISNUMBER(I8)),I8,"")
A9: Aug-2025 | B9: Hubbell | C9: DMC Power | D9: Substation and transmission connector systems | E9: 825 | F9: 130 | G9: 60 | H9: =IF(ISNUMBER(F9),E9/F9,"n/a") | I9: =IF(ISNUMBER(G9),E9/G9,"n/a") | J9: 2026E | K9: 1 | L9: =IF(AND(K9=1,ISNUMBER(H9)),H9,"") | M9: =IF(AND(K9=1,ISNUMBER(I9)),I9,"")
A10: Mar-2025 | B10: Eaton | C10: Fibrebond | D10: Pre-integrated modular power enclosures / skids (data centers, utilities) | E10: 1400 | F10: 378 | G10: 110 | H10: =IF(ISNUMBER(F10),E10/F10,"n/a") | I10: =IF(ISNUMBER(G10),E10/G10,"n/a") | J10: Rev TTM Feb-25; EBITDA 2025E; excl. $240mm assumed retention awards | K10: 1 | L10: =IF(AND(K10=1,ISNUMBER(H10)),H10,"") | M10: =IF(AND(K10=1,ISNUMBER(I10)),I10,"")
A11: Mar-2025 | B11: nVent | C11: Avail Electrical Products Group | D11: Enclosures, switchgear and bus systems for utilities and data centers | E11: 975 | F11: 375 | G11: 78 | H11: =IF(ISNUMBER(F11),E11/F11,"n/a") | I11: 12.5 | J11: TTM; 12.5x stated | K11: 1 | L11: =IF(AND(K11=1,ISNUMBER(H11)),H11,"") | M11: =IF(AND(K11=1,ISNUMBER(I11)),I11,"")
A12: Jun-2024 | B12: nVent | C12: Trachte | D12: Custom-engineered control buildings (utility, data center) | E12: 695 | F12: 250 | G12: 58 | H12: =IF(ISNUMBER(F12),E12/F12,"n/a") | I12: 12 | J12: 2024E; ~12x 'effective' stated | K12: 1 | L12: =IF(AND(K12=1,ISNUMBER(H12)),H12,"") | M12: =IF(AND(K12=1,ISNUMBER(I12)),I12,"")
A13: Oct-2023 | B13: Hubbell | C13: Systems Control | D13: Substation control and relay panels, control buildings | E13: 1100 | F13: 400 | G13: 91.6 | H13: =IF(ISNUMBER(F13),E13/F13,"n/a") | I13: =IF(ISNUMBER(G13),E13/G13,"n/a") | J13: 2024E; ~12x stated | K13: 1 | L13: =IF(AND(K13=1,ISNUMBER(H13)),H13,"") | M13: =IF(AND(K13=1,ISNUMBER(I13)),I13,"")
A14: Apr-2023 | B14: nVent | C14: ECM Industries | D14: Electrical connectors, tools and consumables | E14: 1100 | F14: 415 | G14: 104 | H14: =IF(ISNUMBER(F14),E14/F14,"n/a") | I14: 10.6 | J14: TTM adj.; ~10.6x 'effective' stated | K14: 1 | L14: =IF(AND(K14=1,ISNUMBER(H14)),H14,"") | M14: =IF(AND(K14=1,ISNUMBER(I14)),I14,"")
A15: Sep-2021 | B15: Vertiv | C15: E&I Engineering / Powerbar Gulf | D15: Switchgear, busway, integrated modular power for data centers | E15: 1800 | F15: 460 | G15: 150 | H15: =IF(ISNUMBER(F15),E15/F15,"n/a") | I15: =IF(ISNUMBER(G15),E15/G15,"n/a") | J15: Rev 2021E; EBITDA 2022E pre-synergy; excl. up to $200mm earnout | K15: 1 | L15: =IF(AND(K15=1,ISNUMBER(H15)),H15,"") | M15: =IF(AND(K15=1,ISNUMBER(I15)),I15,"")
A16: Nov-2025 | B16: Eaton | C16: Boyd Thermal | D16: Liquid cooling for AI data centers (thermal, not power) | E16: 9500 | F16: 1700 | G16: 422 | H16: =IF(ISNUMBER(F16),E16/F16,"n/a") | I16: 22.5 | J16: 2026E adj.; 22.5x stated. Excluded: thermal | K16: 0 | L16: =IF(AND(K16=1,ISNUMBER(H16)),H16,"") | M16: =IF(AND(K16=1,ISNUMBER(I16)),I16,"")
A17: Nov-2025 | B17: Vertiv | C17: PurgeRite | D17: Fluid-management services for liquid cooling | E17: 1000 | F17: n/a | G17: n/a | H17: =IF(ISNUMBER(F17),E17/F17,"n/a") | I17: 10 | J17: 2026E post-synergy, stated. Excluded: services/thermal | K17: 0 | L17: =IF(AND(K17=1,ISNUMBER(H17)),H17,"") | M17: =IF(AND(K17=1,ISNUMBER(I17)),I17,"")
A18: Jul-2024 | B18: Quanta Services | C18: Cupertino Electric | D18: Electrical contractor for data centers (not a manufacturer) | E18: 1540 | F18: 2150 | G18: 165 | H18: =IF(ISNUMBER(F18),E18/F18,"n/a") | I18: =IF(ISNUMBER(G18),E18/G18,"n/a") | J18: 2024E adj. midpoints. Excluded: contractor | K18: 0 | L18: =IF(AND(K18=1,ISNUMBER(H18)),H18,"") | M18: =IF(AND(K18=1,ISNUMBER(I18)),I18,"")
A19: Apr-2024 | B19: Prysmian | C19: Encore Wire | D19: US building wire and cable | E19: 4160 | F19: n/a | G19: n/a | H19: =IF(ISNUMBER(F19),E19/F19,"n/a") | I19: 8.2 | J19: 2023A, 8.2x stated (6.3x post-synergy). Excluded: commodity cable | K19: 0 | L19: =IF(AND(K19=1,ISNUMBER(H19)),H19,"") | M19: =IF(AND(K19=1,ISNUMBER(I19)),I19,"")
C21: Maximum | H21: =MAX(L5:L19) | I21: =MAX(M5:M19)
C22: 75th percentile | H22: =QUARTILE(L5:L19,3) | I22: =QUARTILE(M5:M19,3)
C23: Mean | H23: =AVERAGE(L5:L19) | I23: =AVERAGE(M5:M19)
C24: Median | H24: =MEDIAN(L5:L19) | I24: =MEDIAN(M5:M19)
C25: 25th percentile | H25: =QUARTILE(L5:L19,1) | I25: =QUARTILE(M5:M19,1)
C26: Minimum | H26: =MIN(L5:L19) | I26: =MIN(M5:M19)
A28: Implied FPS valuation (applied to FPS CY26E, 25th pct - median - 75th pct; core deals only)
A29: Metric | C29: FPS CY26E metric | D29: 25th pct | E29: Median | F29: 75th pct | G29: Price low | H29: Price mid | I29: Price high
A30: EV / EBITDA | C30: =Comps!M22 | D30: =I25 | E30: =I24 | F30: =I22 | G30: =($C30*D30+(-Inputs!$B$10+Inputs!$B$11))/Inputs!$B$13 | H30: =($C30*E30+(-Inputs!$B$10+Inputs!$B$11))/Inputs!$B$13 | I30: =($C30*F30+(-Inputs!$B$10+Inputs!$B$11))/Inputs!$B$13
A31: EV / revenue | C31: =Comps!K22 | D31: =H25 | E31: =H24 | F31: =H22 | G31: =($C31*D31+(-Inputs!$B$10+Inputs!$B$11))/Inputs!$B$13 | H31: =($C31*E31+(-Inputs!$B$10+Inputs!$B$11))/Inputs!$B$13 | I31: =($C31*F31+(-Inputs!$B$10+Inputs!$B$11))/Inputs!$B$13
A33: Notes: (1) Most acquirers disclose current- or next-year EBITDA, so the multiples are applied to FPS's calendar-2026E EBITDA/revenue (blend of FY26A and FY27E), not a pure LTM figure. Bases differ deal by deal - see the Basis column.
A34: (2) Deals flagged 0 in 'In stats' (thermal, services, contractor, cable) are shown for context only.
A35: (3) Forgent's own formation deals under Neos Partners (MGM Transformer $424.7mm, Oct-23; VanTran $432.7mm, Jun-24; PwrQ $103.0mm; States Manufacturing $68.5mm) disclose price only, so no multiples are available (FPS 424B4).
A36: (4) Precedent multiples include a control premium; FPS trades far above them (~21x FY27E EBITDA at market) because its growth is 3-6x the targets'.

Sheet Summary
A1: Valuation Summary - Football Field ($ per FPS share)
A2: ="Active DCF case: "&Inputs!$C$20&" | Current price $"&TEXT(Inputs!$B$6,"0.00")
A4: Methodology | B4: Low | C4: High | D4: Spread | E4: Midpoint | F4: vs. current
A5: DCF - perpetuity growth (WACC +/-1%, g 2.5-3.5%) | B5: =MIN(Sensitivity!D7:F9) | C5: =MAX(Sensitivity!D7:F9) | D5: =C5-B5 | E5: =(B5+C5)/2 | F5: =E5/Inputs!$B$6-1
A6: DCF - exit multiple (WACC +/-1%, 12-16x) | B6: =MIN(Sensitivity!D15:F17) | C6: =MAX(Sensitivity!D15:F17) | D6: =C6-B6 | E6: =(B6+C6)/2 | F6: =E6/Inputs!$B$6-1
A7: Trading comps - EV / CY27E EBITDA (25th-75th) | B7: =Comps!J28 | C7: =Comps!L28 | D7: =C7-B7 | E7: =(B7+C7)/2 | F7: =E7/Inputs!$B$6-1
A8: Trading comps - EV / CY26E EBITDA (25th-75th) | B8: =Comps!J27 | C8: =Comps!L27 | D8: =C8-B8 | E8: =(B8+C8)/2 | F8: =E8/Inputs!$B$6-1
A9: Precedent transactions - EV / CY26E EBITDA (25th-75th) | B9: =Precedents!G30 | C9: =Precedents!I30 | D9: =C9-B9 | E9: =(B9+C9)/2 | F9: =E9/Inputs!$B$6-1
A10: Analyst price targets (consensus mean) | B10: 57.9 | C10: 57.9 | D10: =C10-B10 | E10: =(B10+C10)/2 | F10: =E10/Inputs!$B$6-1
A12: Current share price | B12: =Inputs!$B$6
A13: DCF point estimate - perpetuity / exit multiple | B13: =DCF!$B$40 | C13: =DCF!$C$40
A14: Market-implied EV / FY27E EBITDA (guidance midpoint) | B14: =Inputs!$B$16/DCF!C7
